#######################################################################
# +-----------------------------------------------------------------+ #
# |                            BO3 object                           | #
# +-----------------------------------------------------------------+ #
#######################################################################

# The descriptions in this file are accurate only for TerrainControl and OTG.
# For MCW and OTG+ these descriptions are only accurate if the BO3 is used as a CustomObject.
# MCW and OTG+ completely reimplemented CustomStructure, check the MCW/OTG+ documentation for more information.

# This is the config file of a custom object.
# If you add this object correctly to your BiomeConfigs, it will spawn in the world.

# This is the creator of this BO3 object
Author: Unknown

# A short description of this BO3 object
Description: This BO3 was converted from a schematic using OTGEdit. The author and description information of the schematic could not be found. If you know who the author of the schematic is then please add this information.

# The BO3 version, don't change this! It can be used by external applications to do a version check.
Version: 3

# The settings mode, WriteAll, WriteWithoutComments or WriteDisable. See WorldConfig.
SettingsMode: WriteDisable

#######################################################################
# +-----------------------------------------------------------------+ #
# |                          Main settings                          | #
# +-----------------------------------------------------------------+ #
#######################################################################

# This needs to be set to true to spawn the object in the Tree and Sapling resources.
Tree: true

# The frequency of the BO3 from 1 to 200. Tries this many times to spawn this BO3 when using the CustomObject(...) resource.
# Ignored by Tree(..), Sapling(..) and CustomStructure(..)
Frequency: 2

# The rarity of the BO3 from 0 to 100. Each spawn attempt has rarity% chance to succeed when using the CustomObject(...) resource.
# Ignored by Tree(..), Sapling(..) and CustomStructure(..)
Rarity: 10

# If you set this to true, the BO3 will be placed with a random rotation.
RotateRandomly: true

# The spawn height of the BO3 - randomY, highestBlock or highestSolidBlock.
SpawnHeight: highestBlock

# The height limits for the BO3.
MinHeight: 0

MaxHeight: 256

# Objects can have other objects attached to it: branches. Branches can also
# have branches attached to it, which can also have branches, etc. This is the
# maximum branch depth for this objects.
MaxBranchDepth: 10

# When spawned with the UseWorld keyword, this BO3 should NOT spawn in the following biomes.
# If you writer.write the BO3 name directly in the BiomeConfigs, this will be ignored.
ExcludedBiomes: All

# To optimise this BO3 for faster loading times you can use Notepad++ to find/replace comments and abbreviate things.
# Notepad++ find/replace with regex:
# Find: ^[#;].* replace to nothing removes all lines starting with # 
# Find: ^\s*$ replace to nothing removes most empty lines 
# Notepad++ find/replace without regex:
# *Warning: This will only work for OTG 1.10.2 v21 / OTG 1.11.2 v6 or higher. B( is not recognised by lower versions.
# Find: Block( replace to B(

#######################################################################
# +-----------------------------------------------------------------+ #
# |                      Source block settings                      | #
# +-----------------------------------------------------------------+ #
#######################################################################

# The block(s) the BO3 should spawn in.
SourceBlocks: AIR

# The maximum percentage of the BO3 that can be outside the SourceBlock.
# The BO3 won't be placed on a location with more blocks outside the SourceBlock than this percentage.
MaxPercentageOutsideSourceBlock: 100

# What to do when a block is about to be placed outside the SourceBlock? (dontPlace, placeAnyway)
OutsideSourceBlock: placeAnyway

#######################################################################
# +-----------------------------------------------------------------+ #
# |                              Blocks                             | #
# +-----------------------------------------------------------------+ #
#######################################################################

# All the blocks used in the BO3 are listed here. Possible blocks:
# Block(x,y,z,id[.data][,nbtfile.nbt) or B(x,y,z,id[.data][,nbtfile.nbt)
# RandomBlock(x,y,z,id[:data][,nbtfile.nbt],chance[,id[:data][,nbtfile.nbt],chance[,...]])
# So RandomBlock(0,0,0,CHEST,chest.nbt,50,CHEST,anotherchest.nbt,100) will spawn a chest at
# the BO3 origin, and give it a 50% chance to have the contents of chest.nbt, or, if that
# fails, a 100% percent chance to have the contents of anotherchest.nbt.

Block(-10,5,4,35)
Block(-10,6,4,35:14)
Block(-9,4,2,35)
Block(-9,5,2,35:14)
Block(-9,5,3,35)
Block(-9,5,4,35)
Block(-9,6,4,35:6)
Block(-9,7,4,35:14)
Block(-9,9,4,35)
Block(-8,5,3,17:13)
Block(-8,5,4,17:13)
Block(-8,5,6,35:6)
Block(-8,6,3,35:6)
Block(-8,6,5,35:14)
Block(-8,7,1,35)
Block(-8,7,4,35:14)
Block(-8,7,5,35:14)
Block(-8,7,6,35)
Block(-8,8,1,35:14)
Block(-8,8,4,35)
Block(-8,9,0,35)
Block(-8,9,1,35:14)
Block(-8,9,4,35)
Block(-8,9,5,35:6)
Block(-8,10,1,35:14)
Block(-8,10,3,35:6)
Block(-8,10,5,35)
Block(-8,12,-2,35:14)
Block(-8,12,-1,35:14)
Block(-8,12,2,35:14)
Block(-8,12,3,35)
Block(-7,3,5,35)
Block(-7,5,1,35:6)
Block(-7,5,2,35)
Block(-7,5,3,17:13)
Block(-7,5,4,35)
Block(-7,6,1,17:13)
Block(-7,6,2,17:13)
Block(-7,6,4,35:6)
Block(-7,7,2,35)
Block(-7,7,3,35:6)
Block(-7,7,6,35:6)
Block(-7,8,2,35)
Block(-7,8,6,35:14)
Block(-7,9,-2,35:14)
Block(-7,9,0,35:6)
Block(-7,9,1,35:14)
Block(-7,9,2,35:6)
Block(-7,9,3,35:14)
Block(-7,9,4,35:6)
Block(-7,10,0,35:6)
Block(-7,10,2,35:14)
Block(-7,10,4,35)
Block(-7,10,5,35:6)
Block(-7,10,6,35)
Block(-7,11,1,35:6)
Block(-7,11,2,35:6)
Block(-7,11,4,35:14)
Block(-7,11,6,35:14)
Block(-7,12,0,35:14)
Block(-7,12,3,35:6)
Block(-7,13,3,35:6)
Block(-6,4,4,35)
Block(-6,5,4,35)
Block(-6,5,5,35)
Block(-6,6,1,17:13)
Block(-6,7,0,35:14)
Block(-6,7,1,17:13)
Block(-6,7,2,35)
Block(-6,7,4,35:6)
Block(-6,8,-2,35)
Block(-6,8,-1,35:14)
Block(-6,8,0,35:14)
Block(-6,8,1,35)
Block(-6,8,2,35:14)
Block(-6,8,3,35:14)
Block(-6,8,4,35)
Block(-6,8,6,35:6)
Block(-6,9,0,35)
Block(-6,9,1,35)
Block(-6,9,2,35:14)
Block(-6,9,3,35:14)
Block(-6,9,4,17:13)
Block(-6,10,-1,35:6)
Block(-6,10,2,35:6)
Block(-6,10,3,35:6)
Block(-6,10,4,35)
Block(-6,10,5,17:13)
Block(-6,11,-3,35)
Block(-6,11,0,35)
Block(-6,11,2,35:14)
Block(-6,11,4,35)
Block(-6,11,5,35:6)
Block(-6,12,-2,35:14)
Block(-6,12,-1,35)
Block(-6,12,0,35)
Block(-6,12,1,35)
Block(-6,12,5,35:6)
Block(-6,13,5,35:14)
Block(-6,14,-2,35)
Block(-6,14,0,35:6)
Block(-6,14,2,35)
Block(-6,14,5,35:14)
Block(-5,6,2,35)
Block(-5,7,1,17:13)
Block(-5,7,2,17:13)
Block(-5,8,0,35:6)
Block(-5,8,3,17:13)
Block(-5,9,-1,35:6)
Block(-5,9,0,35)
Block(-5,9,2,35:14)
Block(-5,9,5,35)
Block(-5,10,-2,35:14)
Block(-5,10,1,35:14)
Block(-5,10,3,35)
Block(-5,10,4,35)
Block(-5,10,5,35)
Block(-5,10,6,35)
Block(-5,11,-2,35)
Block(-5,11,2,35:6)
Block(-5,11,5,35)
Block(-5,11,6,35:14)
Block(-5,12,-4,35:6)
Block(-5,12,-3,35:14)
Block(-5,12,-1,35)
Block(-5,12,1,35)
Block(-5,12,5,35:14)
Block(-5,12,6,35)
Block(-5,13,-2,35:14)
Block(-5,13,-1,35)
Block(-5,13,0,35)
Block(-5,13,2,35:14)
Block(-5,14,-5,35:6)
Block(-5,14,-4,35)
Block(-5,14,3,35:6)
Block(-5,14,4,35)
Block(-5,14,6,35:6)
Block(-5,15,-1,35:6)
Block(-5,15,2,35:14)
Block(-5,15,5,35)
Block(-5,16,4,35:6)
Block(-4,7,1,35:6)
Block(-4,7,2,17:13)
Block(-4,8,1,35:14)
Block(-4,8,2,17:13)
Block(-4,9,0,35:14)
Block(-4,9,4,35:6)
Block(-4,10,-1,35:14)
Block(-4,10,3,35:6)
Block(-4,10,4,35:14)
Block(-4,11,-3,35:6)
Block(-4,11,-2,35:6)
Block(-4,11,-1,35)
Block(-4,11,5,35)
Block(-4,12,-2,17:13)
Block(-4,12,-1,17:13)
Block(-4,12,5,35)
Block(-4,12,6,35)
Block(-4,13,-4,35)
Block(-4,13,-3,17:13)
Block(-4,13,-2,17:13)
Block(-4,13,-1,35:6)
Block(-4,13,4,35:6)
Block(-4,13,5,35)
Block(-4,13,6,35:14)
Block(-4,13,7,35:14)
Block(-4,14,-5,35)
Block(-4,14,-4,35:6)
Block(-4,14,-3,35:6)
Block(-4,14,-1,35:14)
Block(-4,14,0,35:6)
Block(-4,14,1,35:6)
Block(-4,14,4,35:14)
Block(-4,14,6,35:6)
Block(-4,15,-3,35:14)
Block(-4,15,-2,35:14)
Block(-4,15,-1,35:14)
Block(-4,15,1,35)
Block(-4,15,5,35:14)
Block(-3,8,2,17:13)
Block(-3,9,1,17:13)
Block(-3,9,2,17:13)
Block(-3,10,0,17:13)
Block(-3,10,1,17:13)
Block(-3,11,-4,35:6)
Block(-3,11,-3,35:14)
Block(-3,11,0,17:13)
Block(-3,11,4,35:6)
Block(-3,11,6,35:14)
Block(-3,11,7,35)
Block(-3,12,-6,35:14)
Block(-3,12,-5,35:14)
Block(-3,12,-4,35:6)
Block(-3,12,-2,35:6)
Block(-3,12,0,35:14)
Block(-3,12,3,35:6)
Block(-3,12,4,35)
Block(-3,12,5,35:6)
Block(-3,12,6,35:6)
Block(-3,12,7,35)
Block(-3,13,-8,35)
Block(-3,13,-6,35:14)
Block(-3,13,-4,35)
Block(-3,13,-2,35:14)
Block(-3,13,-1,35:14)
Block(-3,13,1,35:14)
Block(-3,13,2,35:14)
Block(-3,13,4,35:14)
Block(-3,13,5,17:13)
Block(-3,13,6,35)
Block(-3,14,-8,35)
Block(-3,14,-7,35:6)
Block(-3,14,-3,35:6)
Block(-3,14,4,35:6)
Block(-3,14,5,17:13)
Block(-3,14,6,35:6)
Block(-3,15,-8,35:6)
Block(-3,15,-6,35)
Block(-3,15,-5,35:6)
Block(-3,15,-1,35:6)
Block(-3,15,1,35:14)
Block(-3,15,4,35:14)
Block(-3,15,5,35:14)
Block(-2,9,1,17:13)
Block(-2,10,-1,35:6)
Block(-2,10,1,17:13)
Block(-2,11,-7,35:6)
Block(-2,11,-1,35:14)
Block(-2,11,5,35)
Block(-2,12,-8,35)
Block(-2,12,-7,35:6)
Block(-2,12,-6,35:14)
Block(-2,12,-2,35:6)
Block(-2,12,-1,35)
Block(-2,12,1,35)
Block(-2,12,5,17:13)
Block(-2,13,-10,35:6)
Block(-2,13,-8,35:14)
Block(-2,13,-6,35:6)
Block(-2,13,-5,35:14)
Block(-2,13,-4,35:14)
Block(-2,13,-1,35:6)
Block(-2,13,1,35)
Block(-2,13,2,35:6)
Block(-2,13,5,17:13)
Block(-2,13,7,35)
Block(-2,14,-2,35)
Block(-2,14,1,35)
Block(-2,14,3,35:6)
Block(-2,14,4,35:14)
Block(-2,14,5,35:14)
Block(-2,14,7,35:6)
Block(-2,15,-8,35:6)
Block(-2,15,-6,35:6)
Block(-2,15,-4,35:6)
Block(-2,15,-1,35)
Block(-2,15,1,35)
Block(-2,15,3,35:14)
Block(-2,15,4,35)
Block(-1,5,-5,17:13)
Block(-1,9,1,17:13)
Block(-1,9,2,17:13)
Block(-1,10,-9,35:14)
Block(-1,10,3,17:13)
Block(-1,10,4,17:13)
Block(-1,11,-10,35:6)
Block(-1,11,-8,35:14)
Block(-1,11,4,17:13)
Block(-1,11,7,35:6)
Block(-1,12,-8,35:6)
Block(-1,12,-7,35)
Block(-1,12,1,35:6)
Block(-1,12,4,17:13)
Block(-1,12,5,17:13)
Block(-1,12,7,35)
Block(-1,13,-10,35)
Block(-1,13,-8,35:6)
Block(-1,13,-5,35:14)
Block(-1,13,-4,35:14)
Block(-1,13,2,35:6)
Block(-1,13,3,17:13)
Block(-1,13,5,35:14)
Block(-1,13,6,35:14)
Block(-1,14,-9,35:14)
Block(-1,14,-4,35:6)
Block(-1,14,2,17:13)
Block(-1,14,5,35)
Block(-1,14,6,35:14)
Block(-1,15,0,35:14)
Block(-1,15,1,35:14)
Block(-1,15,2,35:6)
Block(-1,16,1,35)
Block(0,0,-1,17:13)
Block(0,1,-1,85)
Block(0,6,-4,17:13)
Block(0,7,0,17:13)
Block(0,7,1,17:13)
Block(0,8,0,17:13)
Block(0,8,1,17:13)
Block(0,9,1,17:13)
Block(0,9,2,17:13)
Block(0,9,3,17:13)
Block(0,10,-8,35:14)
Block(0,10,3,17:13)
Block(0,11,-8,35:6)
Block(0,11,-7,35)
Block(0,11,4,35)
Block(0,12,-10,35:6)
Block(0,12,-9,35:14)
Block(0,12,-8,17:13)
Block(0,12,-7,35:6)
Block(0,12,1,35:6)
Block(0,12,4,35:14)
Block(0,13,-8,35:14)
Block(0,13,-6,35:14)
Block(0,13,-1,35:14)
Block(0,13,3,35:6)
Block(0,14,-9,35)
Block(0,14,-8,35:14)
Block(0,14,0,35:14)
Block(0,14,1,17:13)
Block(0,14,2,35:6)
Block(0,14,3,35:6)
Block(0,14,4,35:14)
Block(0,15,1,35)
Block(0,15,2,35:6)
Block(0,15,3,35:14)
Block(0,16,1,35:14)
Block(0,16,2,35:6)
Block(1,0,-5,85)
Block(1,0,-4,17:13)
Block(1,0,-2,17:13)
Block(1,0,-1,17:13)
Block(1,0,0,85)
Block(1,1,-4,17:13)
Block(1,1,-2,85)
Block(1,2,-3,85)
Block(1,3,-3,85)
Block(1,3,-2,17:13)
Block(1,4,-2,17:13)
Block(1,5,-2,17:13)
Block(1,5,-1,17:13)
Block(1,6,-2,17:13)
Block(1,6,-1,17:13)
Block(1,6,0,17:13)
Block(1,7,-4,17:13)
Block(1,7,-3,17:13)
Block(1,7,-2,17:13)
Block(1,7,-1,17:13)
Block(1,7,0,17:13)
Block(1,7,1,17:13)
Block(1,8,1,17:13)
Block(1,8,2,17:13)
Block(1,9,1,17:13)
Block(1,9,2,17:13)
Block(1,10,-5,35)
Block(1,11,-10,35:14)
Block(1,11,-7,17:13)
Block(1,11,-6,35:6)
Block(1,11,4,35:6)
Block(1,11,6,35:6)
Block(1,12,-7,35:6)
Block(1,12,-6,35:14)
Block(1,12,-5,35:14)
Block(1,12,7,35:14)
Block(1,13,-8,35:14)
Block(1,13,-6,35:14)
Block(1,13,0,35:6)
Block(1,13,3,35:14)
Block(1,13,7,35:6)
Block(1,14,1,35:6)
Block(1,14,2,35:6)
Block(1,14,3,35:14)
Block(1,15,-1,35:6)
Block(1,15,0,35:6)
Block(1,15,1,35:6)
Block(1,15,3,35:14)
Block(1,16,1,35:14)
Block(2,0,-2,17:13)
Block(2,0,-1,85)
Block(2,1,-5,85)
Block(2,1,-4,17:13)
Block(2,1,-3,17:13)
Block(2,1,-2,17:13)
Block(2,1,-1,17:13)
Block(2,2,-3,17:13)
Block(2,2,-2,85)
Block(2,3,-4,85)
Block(2,3,-3,17:13)
Block(2,3,-2,17:13)
Block(2,4,-3,17:13)
Block(2,4,-2,17:13)
Block(2,5,-2,17:13)
Block(2,5,-1,17:13)
Block(2,6,-2,17:13)
Block(2,6,-1,17:13)
Block(2,6,0,17:13)
Block(2,7,-3,17:13)
Block(2,7,-2,17:13)
Block(2,7,0,17:13)
Block(2,7,1,17:13)
Block(2,8,-3,17:13)
Block(2,10,-7,17:13)
Block(2,11,-7,17:13)
Block(2,11,-6,35:14)
Block(2,12,-9,35:14)
Block(2,12,-8,35:14)
Block(2,12,-7,35)
Block(2,12,-6,35:6)
Block(2,12,-5,35:6)
Block(2,12,-4,35:6)
Block(2,12,-2,35)
Block(2,13,-10,35:6)
Block(2,13,-8,35:14)
Block(2,13,-6,35:6)
Block(2,13,-5,35:6)
Block(2,13,-3,35:6)
Block(2,13,-2,35:14)
Block(2,13,0,35:6)
Block(2,13,2,35:6)
Block(2,14,-10,35)
Block(2,14,-7,35:14)
Block(2,14,-6,35:6)
Block(2,14,-4,35:6)
Block(2,14,-2,35:14)
Block(2,14,-1,35:14)
Block(2,14,1,35:14)
Block(2,14,2,35:6)
Block(2,14,3,35:14)
Block(2,14,9,35)
Block(2,15,-8,35)
Block(2,15,-7,35:14)
Block(2,15,1,35:6)
Block(2,15,2,35:14)
Block(2,15,3,35:14)
Block(2,16,0,35)
Block(3,1,-4,85)
Block(3,1,-3,17:13)
Block(3,1,-2,17:13)
Block(3,2,-4,17:13)
Block(3,2,-3,17:13)
Block(3,2,-2,17:13)
Block(3,3,-3,17:13)
Block(3,3,-2,17:13)
Block(3,4,-2,17:13)
Block(3,5,-2,17:13)
Block(3,5,-1,17:13)
Block(3,7,0,17:13)
Block(3,7,1,17:13)
Block(3,8,-4,17:13)
Block(3,8,-3,17:13)
Block(3,8,1,17:13)
Block(3,9,-6,17:13)
Block(3,9,-4,17:13)
Block(3,10,-8,35:6)
Block(3,10,-7,17:13)
Block(3,10,-6,35)
Block(3,10,7,35)
Block(3,11,-9,35:6)
Block(3,11,-8,35)
Block(3,11,-7,35:14)
Block(3,11,-5,35:14)
Block(3,11,-4,35:6)
Block(3,11,5,17:13)
Block(3,11,6,17:13)
Block(3,11,7,17:13)
Block(3,11,10,35:14)
Block(3,12,-8,35)
Block(3,12,-7,35:6)
Block(3,12,-6,35:6)
Block(3,12,-5,35)
Block(3,12,-4,35)
Block(3,12,6,35:14)
Block(3,12,7,17:13)
Block(3,12,8,17:13)
Block(3,12,9,35)
Block(3,13,-9,35:6)
Block(3,13,-6,35)
Block(3,13,-3,35:14)
Block(3,13,-2,35:14)
Block(3,13,-1,35:14)
Block(3,13,1,35:6)
Block(3,13,2,35)
Block(3,13,8,35:6)
Block(3,14,-9,35)
Block(3,14,-7,35:6)
Block(3,14,-6,35:14)
Block(3,14,-4,35:14)
Block(3,14,1,35)
Block(3,14,7,35:6)
Block(3,15,-8,35:14)
Block(3,15,-7,35)
Block(3,15,-4,35)
Block(3,15,-2,35)
Block(3,15,1,35:6)
Block(3,15,2,35)
Block(3,15,6,35:14)
Block(3,16,-8,35:14)
Block(3,16,-7,35)
Block(3,16,-4,35:6)
Block(3,16,-2,35:6)
Block(3,16,0,35:14)
Block(3,16,3,35:14)
Block(4,0,-4,85)
Block(4,1,-4,17:13)
Block(4,1,-3,17:13)
Block(4,2,-4,17:13)
Block(4,2,-3,17:13)
Block(4,3,-4,85)
Block(4,8,1,17:13)
Block(4,9,-5,17:13)
Block(4,9,-4,17:13)
Block(4,9,1,17:13)
Block(4,9,2,17:13)
Block(4,10,-8,17:13)
Block(4,10,-7,17:13)
Block(4,10,-6,35:14)
Block(4,10,2,17:13)
Block(4,10,3,17:13)
Block(4,10,4,17:13)
Block(4,10,5,17:13)
Block(4,11,-9,35:6)
Block(4,11,-8,35)
Block(4,11,-6,35)
Block(4,11,-4,35:14)
Block(4,11,-3,35:14)
Block(4,11,-2,35:6)
Block(4,11,1,17:13)
Block(4,11,2,17:13)
Block(4,11,5,17:13)
Block(4,11,7,35:6)
Block(4,12,-8,35:14)
Block(4,12,-7,35)
Block(4,12,-6,35:6)
Block(4,12,-5,35:6)
Block(4,12,-4,35:6)
Block(4,12,-3,35)
Block(4,12,-2,35:14)
Block(4,12,3,35:14)
Block(4,12,7,35)
Block(4,12,8,17:13)
Block(4,13,-8,35)
Block(4,13,-7,35:6)
Block(4,13,-6,35:6)
Block(4,13,-4,35)
Block(4,13,-3,35:14)
Block(4,13,-2,35)
Block(4,13,-1,35)
Block(4,13,0,35)
Block(4,13,1,35:14)
Block(4,13,5,35)
Block(4,13,8,17:13)
Block(4,13,9,35)
Block(4,14,-7,35)
Block(4,14,-5,35:6)
Block(4,14,-4,35)
Block(4,14,-3,35:6)
Block(4,14,-1,35:6)
Block(4,14,0,35)
Block(4,14,1,35)
Block(4,14,2,35:6)
Block(4,14,5,35:6)
Block(4,14,6,35:6)
Block(4,14,7,35)
Block(4,14,8,35:6)
Block(4,15,-7,35)
Block(4,15,-5,35:6)
Block(4,15,-4,35:6)
Block(4,15,-2,35:6)
Block(4,15,-1,35)
Block(4,15,1,35:6)
Block(4,16,-6,35:14)
Block(4,16,-2,35)
Block(4,16,2,35:14)
Block(5,1,-4,17:13)
Block(5,1,-3,85)
Block(5,2,-3,85)
Block(5,10,-8,17:13)
Block(5,10,-6,35)
Block(5,11,-11,35:6)
Block(5,11,-10,35)
Block(5,11,-8,17:13)
Block(5,11,-7,35:14)
Block(5,11,0,35:6)
Block(5,11,1,17:13)
Block(5,11,7,35:6)
Block(5,11,8,35)
Block(5,12,-11,35)
Block(5,12,-8,35:6)
Block(5,12,-6,35:14)
Block(5,12,-4,35:6)
Block(5,12,-2,35)
Block(5,12,0,35)
Block(5,12,2,35:14)
Block(5,12,3,35:14)
Block(5,12,6,35:14)
Block(5,13,-8,35)
Block(5,13,-7,35:6)
Block(5,13,-5,35:14)
Block(5,13,-2,35:14)
Block(5,13,-1,35:6)
Block(5,13,0,35:14)
Block(5,13,1,35:6)
Block(5,13,2,35:6)
Block(5,13,3,35)
Block(5,13,4,35:6)
Block(5,13,6,35:14)
Block(5,13,7,35)
Block(5,13,8,17:13)
Block(5,14,-8,35:14)
Block(5,14,-7,35:6)
Block(5,14,-3,35:6)
Block(5,14,-2,35:14)
Block(5,14,0,35)
Block(5,14,1,35:14)
Block(5,14,3,35:6)
Block(5,14,4,35)
Block(5,14,6,35:6)
Block(5,14,8,35)
Block(5,15,-4,35:6)
Block(5,15,-1,35)
Block(5,15,0,35)
Block(5,15,3,35)
Block(5,15,4,35:14)
Block(5,15,6,35:6)
Block(5,15,9,35)
Block(5,16,1,35)
Block(6,0,-3,85)
Block(6,1,-4,17:13)
Block(6,1,-3,17:13)
Block(6,10,-9,35:14)
Block(6,11,-9,35:14)
Block(6,11,-8,17:13)
Block(6,11,-6,35:14)
Block(6,11,-5,35:6)
Block(6,11,7,35:6)
Block(6,12,-9,17:13)
Block(6,12,-7,35:14)
Block(6,12,-6,35)
Block(6,12,-5,35:14)
Block(6,12,-4,35:14)
Block(6,12,-3,35:14)
Block(6,12,0,17:13)
Block(6,12,1,17:13)
Block(6,12,2,35:6)
Block(6,12,3,35:14)
Block(6,12,6,35:14)
Block(6,12,10,35)
Block(6,13,-11,35:6)
Block(6,13,-8,35:6)
Block(6,13,-6,35:14)
Block(6,13,-5,35:14)
Block(6,13,-3,35:14)
Block(6,13,-2,35:14)
Block(6,13,-1,35:14)
Block(6,13,1,35:14)
Block(6,13,9,35:14)
Block(6,13,10,35)
Block(6,14,-9,35:6)
Block(6,14,-7,35:6)
Block(6,14,-6,35:14)
Block(6,14,-3,35:6)
Block(6,14,-2,35)
Block(6,14,-1,35)
Block(6,14,0,35:14)
Block(6,14,1,35:14)
Block(6,14,3,35)
Block(6,14,4,35:6)
Block(6,15,-6,35:14)
Block(6,15,-3,35)
Block(6,15,-2,35:14)
Block(6,15,6,35:14)
Block(6,15,8,35:6)
Block(6,16,1,35)
Block(7,0,-5,85)
Block(7,0,-4,17:13)
Block(7,0,-3,17:13)
Block(7,1,-4,17:13)
Block(7,1,-3,17:13)
Block(7,11,-11,35)
Block(7,11,-5,35:6)
Block(7,11,-1,35)
Block(7,11,0,35:6)
Block(7,11,2,35:14)
Block(7,12,-9,35:6)
Block(7,12,-5,35:14)
Block(7,12,-4,35)
Block(7,12,-3,35:6)
Block(7,12,-2,35)
Block(7,12,-1,17:13)
Block(7,12,2,35)
Block(7,12,3,35:14)
Block(7,12,8,35:14)
Block(7,13,-6,35)
Block(7,13,-5,35:6)
Block(7,13,-2,17:13)
Block(7,13,-1,17:13)
Block(7,13,0,35:6)
Block(7,13,1,35)
Block(7,13,2,17:13)
Block(7,13,3,35)
Block(7,14,-9,35:14)
Block(7,14,-5,35:14)
Block(7,14,-3,35:14)
Block(7,14,-2,35)
Block(7,14,-1,35:6)
Block(7,14,0,35:6)
Block(7,14,2,35:14)
Block(7,14,7,35)
Block(7,15,-6,35)
Block(7,15,-2,35:14)
Block(7,15,-1,35:14)
Block(8,0,-4,85)
Block(8,0,-3,17:13)
Block(8,0,-2,17:13)
Block(8,0,-1,17:13)
Block(8,0,0,85)
Block(8,11,-9,35)
Block(8,11,-8,35:14)
Block(8,11,-6,35:14)
Block(8,11,2,35:6)
Block(8,12,-8,35)
Block(8,12,-4,35:14)
Block(8,12,-3,35:14)
Block(8,12,1,35:6)
Block(8,12,2,35:14)
Block(8,13,-9,35)
Block(8,13,-8,35:14)
Block(8,13,-2,35:6)
Block(8,13,0,35)
Block(8,13,2,17:13)
Block(8,14,-3,35:6)
Block(8,14,-1,35:6)
Block(8,14,2,35)
Block(8,14,3,35:14)
Block(8,15,-6,35:14)
Block(8,15,-1,35:14)
Block(9,11,-5,35:14)
Block(9,12,-7,35:14)
Block(9,12,-6,35:6)
Block(9,12,-4,35)
Block(9,12,-3,35:14)
Block(9,12,-2,35:14)
Block(9,12,2,35:14)
Block(9,13,-6,35:6)
Block(9,13,-2,35)
Block(9,13,-1,35:14)
Block(9,14,4,35)
Block(9,15,1,35:6)
Block(10,13,2,35)
Block(10,14,3,35:6)


#######################################################################
# +-----------------------------------------------------------------+ #
# |                             Entities                            | #
# +-----------------------------------------------------------------+ #
#######################################################################

# Entity() spawns an entity instead of a block. The entity is spawned only once when the BO3 is spawned.
# Entities are persistent by default so they don't de-spawn when no player is near, they are only unloaded.
# Usage: Entity(x,y,z,mobName,groupSize,NameTagOrNBTFileName) or Entity(x,y,z,mobName,groupSize)
# Use /tc entities or /otg entities to get a list of entities that can be used as mobName, this includes entities added by other mods.
# NameTagOrNBTFileName can be either a nametag for the mob or an nbt file (such as mymobinfo.nbt or mymobinfo.txt).
# When using a text file you can use the same mob spawning parameters used with the /summon command to equip the
# entity and give it custom attributes etc. You can copy the DATA part of a summon command including surrounding
# curly braces to a .txt file, for instance for: "/summon Skeleton x y z {DATA}"

#######################################################################
# +-----------------------------------------------------------------+ #
# |                            BO3 checks                           | #
# +-----------------------------------------------------------------+ #
#######################################################################

# Require a condition at a certain location in order for the BO3 to be spawned.
# BlockCheck(x,y,z,BlockName[,BlockName[,...]]) - one of the blocks must be at the location
# BlockCheckNot(x,y,z,BlockName[,BlockName[,...]]) - all the blocks must not be at the location
# LightCheck(x,y,z,minLightLevel,maxLightLevel) - light must be between min and max (inclusive)

# You can use "Solid" as a BlockName for matching all solid blocks or "All" to match all blocks that aren't air.

# Examples:
#   BlockCheck(0,-1,0,GRASS,DIRT)  Require grass or dirt just below the object
#   BlockCheck(0,-1,0,Solid)       Require any solid block just below the object
#   BlockCheck(0,-1,0,WOOL)        Require any type of wool just below the object
#   BlockCheck(0,-1,0,WOOL:0)      Require white wool just below the object
#   BlockCheckNot(0,-1,0,WOOL:0)   Require that there is no white wool below the object
#   LightCheck(0,0,0,0,1)          Require almost complete darkness just below the object
BlockCheck(0,-1,0,GRASS,DIRT)
