#######################################################################
# +-----------------------------------------------------------------+ #
# |                            BO3 object                           | #
# +-----------------------------------------------------------------+ #
#######################################################################

# The descriptions in this file are accurate only for TerrainControl and OTG.
# For MCW and OTG+ these descriptions are only accurate if the BO3 is used as a CustomObject.
# MCW and OTG+ completely reimplemented CustomStructure, check the MCW/OTG+ documentation for more information.

# This is the config file of a custom object.
# If you add this object correctly to your BiomeConfigs, it will spawn in the world.

# This is the creator of this BO3 object
Author: Unknown

# A short description of this BO3 object
Description: This BO3 was converted from a schematic using OTGEdit. The author and description information of the schematic could not be found. If you know who the author of the schematic is then please add this information.

# The BO3 version, don't change this! It can be used by external applications to do a version check.
Version: 3

# The settings mode, WriteAll, WriteWithoutComments or WriteDisable. See WorldConfig.
SettingsMode: WriteDisable

#######################################################################
# +-----------------------------------------------------------------+ #
# |                          Main settings                          | #
# +-----------------------------------------------------------------+ #
#######################################################################

# This needs to be set to true to spawn the object in the Tree and Sapling resources.
Tree: true

# The frequency of the BO3 from 1 to 200. Tries this many times to spawn this BO3 when using the CustomObject(...) resource.
# Ignored by Tree(..), Sapling(..) and CustomStructure(..)
Frequency: 1

# The rarity of the BO3 from 0 to 100. Each spawn attempt has rarity% chance to succeed when using the CustomObject(...) resource.
# Ignored by Tree(..), Sapling(..) and CustomStructure(..)
Rarity: 2

# If you set this to true, the BO3 will be placed with a random rotation.
RotateRandomly: true

# The spawn height of the BO3 - randomY, highestBlock or highestSolidBlock.
SpawnHeight: highestSolidBlock

# The height limits for the BO3.
MinHeight: 64

MaxHeight: 200

# Objects can have other objects attached to it: branches. Branches can also
# have branches attached to it, which can also have branches, etc. This is the
# maximum branch depth for this objects.
MaxBranchDepth: 10

# When spawned with the UseWorld keyword, this BO3 should NOT spawn in the following biomes.
# If you writer.write the BO3 name directly in the BiomeConfigs, this will be ignored.
ExcludedBiomes: All

# To optimise this BO3 for faster loading times you can use Notepad++ to find/replace comments and abbreviate things.
# Notepad++ find/replace with regex:
# Find: ^[#;].* replace to nothing removes all lines starting with # 
# Find: ^\s*$ replace to nothing removes most empty lines 
# Notepad++ find/replace without regex:
# *Warning: This will only work for OTG 1.10.2 v21 / OTG 1.11.2 v6 or higher. B( is not recognised by lower versions.
# Find: Block( replace to B(

#######################################################################
# +-----------------------------------------------------------------+ #
# |                      Source block settings                      | #
# +-----------------------------------------------------------------+ #
#######################################################################

# The block(s) the BO3 should spawn in.
SourceBlocks: AIR

# The maximum percentage of the BO3 that can be outside the SourceBlock.
# The BO3 won't be placed on a location with more blocks outside the SourceBlock than this percentage.
MaxPercentageOutsideSourceBlock: 100

# What to do when a block is about to be placed outside the SourceBlock? (dontPlace, placeAnyway)
OutsideSourceBlock: placeAnyway

#######################################################################
# +-----------------------------------------------------------------+ #
# |                              Blocks                             | #
# +-----------------------------------------------------------------+ #
#######################################################################

# All the blocks used in the BO3 are listed here. Possible blocks:
# Block(x,y,z,id[.data][,nbtfile.nbt) or B(x,y,z,id[.data][,nbtfile.nbt)
# RandomBlock(x,y,z,id[:data][,nbtfile.nbt],chance[,id[:data][,nbtfile.nbt],chance[,...]])
# So RandomBlock(0,0,0,CHEST,chest.nbt,50,CHEST,anotherchest.nbt,100) will spawn a chest at
# the BO3 origin, and give it a 50% chance to have the contents of chest.nbt, or, if that
# fails, a 100% percent chance to have the contents of anotherchest.nbt.

Block(-11,23,6,162:13)
Block(-11,23,7,162:13)
Block(-10,22,7,162:13)
Block(-10,22,8,162:13)
Block(-10,23,7,162:13)
Block(-9,11,1,162:13)
Block(-9,11,2,162:13)
Block(-9,12,2,162:13)
Block(-9,17,-5,162:13)
Block(-9,17,-4,162:13)
Block(-9,21,8,162:13)
Block(-9,21,9,162:13)
Block(-9,22,8,162:13)
Block(-8,11,0,162:13)
Block(-8,12,3,162:13)
Block(-8,13,3,162:13)
Block(-8,13,4,162:13)
Block(-8,17,-4,162:13)
Block(-8,17,-3,162:13)
Block(-8,18,-3,162:13)
Block(-8,19,9,162:13)
Block(-8,20,9,162:13)
Block(-8,21,9,162:13)
Block(-8,24,-3,162:13)
Block(-8,24,-2,162:13)
Block(-8,25,-4,162:13)
Block(-8,25,-3,162:13)
Block(-7,13,4,162:13)
Block(-7,14,4,162:13)
Block(-7,18,-3,162:13)
Block(-7,18,-2,162:13)
Block(-7,18,7,162:13)
Block(-7,18,8,162:13)
Block(-7,19,8,162:13)
Block(-7,19,9,162:13)
Block(-7,22,-1,162:13)
Block(-7,23,-2,162:13)
Block(-7,23,-1,162:13)
Block(-7,24,-2,162:13)
Block(-6,14,4,162:13)
Block(-6,15,4,162:13)
Block(-6,15,5,162:13)
Block(-6,16,6,162:13)
Block(-6,17,6,162:13)
Block(-6,17,7,162:13)
Block(-6,18,-2,162:13)
Block(-6,18,7,162:13)
Block(-6,19,-2,162:13)
Block(-6,20,-2,162:13)
Block(-6,20,-1,162:13)
Block(-6,21,-1,162:13)
Block(-6,22,-1,162:13)
Block(-5,11,-7,162:13)
Block(-5,13,8,162:13)
Block(-5,14,7,162:13)
Block(-5,15,4,162:13)
Block(-5,15,5,162:13)
Block(-5,15,7,162:13)
Block(-5,16,5,162:13)
Block(-5,16,6,162:13)
Block(-5,19,-3,162:13)
Block(-5,19,-2,162:13)
Block(-5,22,-1,162:13)
Block(-5,22,0,162:13)
Block(-4,12,-6,162:13)
Block(-4,13,-6,162:13)
Block(-4,15,5,162:13)
Block(-4,15,6,162:13)
Block(-4,15,7,162:13)
Block(-4,16,5,162:13)
Block(-4,18,-4,162:13)
Block(-4,18,-3,162:13)
Block(-4,19,-4,162:13)
Block(-4,19,-3,162:13)
Block(-4,23,0,162:13)
Block(-3,13,-6,162:13)
Block(-3,14,5,162:13)
Block(-3,15,5,162:13)
Block(-3,15,6,162:13)
Block(-3,16,6,162:13)
Block(-3,17,-4,162:13)
Block(-3,18,-6,162:13)
Block(-3,18,-5,162:13)
Block(-3,18,-4,162:13)
Block(-3,19,-10,162:13)
Block(-3,19,-9,162:13)
Block(-3,20,-8,162:13)
Block(-3,21,13,162:13)
Block(-3,22,13,162:13)
Block(-3,23,13,162:13)
Block(-3,23,14,162:13)
Block(-3,24,14,162:13)
Block(-3,24,15,162:13)
Block(-2,1,1,162:13)
Block(-2,13,-8,162:13)
Block(-2,13,-7,162:13)
Block(-2,13,-6,162:13)
Block(-2,14,-7,162:13)
Block(-2,14,-6,162:13)
Block(-2,14,-5,162:13)
Block(-2,14,6,162:13)
Block(-2,15,-5,162:13)
Block(-2,15,-4,162:13)
Block(-2,15,5,162:13)
Block(-2,15,6,162:13)
Block(-2,15,7,162:13)
Block(-2,16,-4,162:13)
Block(-2,16,-3,162:13)
Block(-2,16,6,162:13)
Block(-2,17,-4,162:13)
Block(-2,18,-6,162:13)
Block(-2,19,-11,162:13)
Block(-2,19,-7,162:13)
Block(-2,19,-6,162:13)
Block(-2,19,12,162:13)
Block(-2,20,-8,162:13)
Block(-2,20,-7,162:13)
Block(-2,20,12,162:13)
Block(-2,21,12,162:13)
Block(-1,1,1,162:13)
Block(-1,1,2,188)
Block(-1,1,3,188)
Block(-1,1,8,162:13)
Block(-1,2,1,162:13)
Block(-1,2,2,162:13)
Block(-1,2,3,162:13)
Block(-1,12,-10,162:13)
Block(-1,13,-10,162:13)
Block(-1,13,-9,162:13)
Block(-1,13,-8,162:13)
Block(-1,15,-3,162:13)
Block(-1,15,6,162:13)
Block(-1,15,7,162:13)
Block(-1,16,-4,162:13)
Block(-1,16,-3,162:13)
Block(-1,16,-2,162:13)
Block(-1,16,6,162:13)
Block(-1,16,7,162:13)
Block(-1,17,-3,162:13)
Block(-1,19,11,162:13)
Block(-1,19,12,162:13)
Block(-1,25,8,162:13)
Block(-1,26,8,162:13)
Block(0,1,6,188)
Block(0,1,7,188)
Block(0,1,8,162:13)
Block(0,2,3,162:13)
Block(0,2,5,162:13)
Block(0,2,6,162:13)
Block(0,3,3,162:13)
Block(0,3,5,162:13)
Block(0,3,6,162:13)
Block(0,4,3,188)
Block(0,14,-1,162:13)
Block(0,15,-3,162:13)
Block(0,15,-2,162:13)
Block(0,15,-1,162:13)
Block(0,15,7,162:13)
Block(0,16,-3,162:13)
Block(0,16,-2,162:13)
Block(0,16,6,162:13)
Block(0,16,7,162:13)
Block(0,17,12,162:13)
Block(0,18,10,162:13)
Block(0,18,11,162:13)
Block(0,19,11,162:13)
Block(0,24,7,162:13)
Block(0,25,7,162:13)
Block(0,25,8,162:13)
Block(1,1,0,162:13)
Block(1,1,7,162:13)
Block(1,1,8,162:13)
Block(1,2,6,162:13)
Block(1,2,7,162:13)
Block(1,3,3,162:13)
Block(1,3,4,162:13)
Block(1,3,5,162:13)
Block(1,3,6,188)
Block(1,4,3,162:13)
Block(1,4,4,162:13)
Block(1,12,0,162:13)
Block(1,12,1,162:13)
Block(1,13,-1,162:13)
Block(1,13,0,162:13)
Block(1,13,1,162:13)
Block(1,14,-2,162:13)
Block(1,14,-1,162:13)
Block(1,14,0,162:13)
Block(1,15,-3,162:13)
Block(1,15,-2,162:13)
Block(1,15,-1,162:13)
Block(1,15,13,162:13)
Block(1,16,-4,162:13)
Block(1,16,-3,162:13)
Block(1,16,7,162:13)
Block(1,16,8,162:13)
Block(1,16,12,162:13)
Block(1,17,6,162:13)
Block(1,17,7,162:13)
Block(1,17,8,162:13)
Block(1,17,9,162:13)
Block(1,18,9,162:13)
Block(1,18,10,162:13)
Block(1,24,6,162:13)
Block(1,24,7,162:13)
Block(2,1,0,162:13)
Block(2,3,-5,162:13)
Block(2,3,4,162:13)
Block(2,3,5,188)
Block(2,4,-5,162:13)
Block(2,4,-4,162:13)
Block(2,4,-3,162:13)
Block(2,4,3,162:13)
Block(2,4,4,162:13)
Block(2,5,-4,162:13)
Block(2,5,-3,162:13)
Block(2,5,-2,162:13)
Block(2,5,4,188)
Block(2,9,1,162:13)
Block(2,10,1,162:13)
Block(2,10,2,162:13)
Block(2,11,1,162:13)
Block(2,11,2,162:13)
Block(2,11,3,162:13)
Block(2,12,-1,162:13)
Block(2,12,0,162:13)
Block(2,12,1,162:13)
Block(2,12,2,162:13)
Block(2,12,3,162:13)
Block(2,13,-1,162:13)
Block(2,13,0,162:13)
Block(2,13,3,162:13)
Block(2,14,-1,162:13)
Block(2,16,-4,162:13)
Block(2,16,7,162:13)
Block(2,16,8,162:13)
Block(2,17,-5,162:13)
Block(2,17,-4,162:13)
Block(2,17,7,162:13)
Block(2,17,8,162:13)
Block(2,18,7,162:13)
Block(2,24,5,162:13)
Block(2,24,6,162:13)
Block(2,25,4,162:13)
Block(2,25,5,162:13)
Block(3,1,-5,188)
Block(3,1,0,162:13)
Block(3,1,1,188)
Block(3,2,-6,162:13)
Block(3,2,-5,162:13)
Block(3,2,-1,162:13)
Block(3,2,0,162:13)
Block(3,3,-5,162:13)
Block(3,3,-2,162:13)
Block(3,3,-1,162:13)
Block(3,4,-5,162:13)
Block(3,4,-4,162:13)
Block(3,4,-3,162:13)
Block(3,4,-2,162:13)
Block(3,4,-1,162:13)
Block(3,4,3,162:13)
Block(3,4,4,162:13)
Block(3,5,-3,162:13)
Block(3,5,-2,162:13)
Block(3,5,-1,162:13)
Block(3,5,3,162:13)
Block(3,6,-2,162:13)
Block(3,6,-1,162:13)
Block(3,8,-1,162:13)
Block(3,8,0,162:13)
Block(3,8,1,162:13)
Block(3,9,-1,162:13)
Block(3,9,0,162:13)
Block(3,9,1,162:13)
Block(3,9,2,162:13)
Block(3,10,0,162:13)
Block(3,10,1,162:13)
Block(3,10,2,162:13)
Block(3,10,3,162:13)
Block(3,11,0,162:13)
Block(3,11,1,162:13)
Block(3,11,2,162:13)
Block(3,11,3,162:13)
Block(3,11,4,162:13)
Block(3,12,-11,162:13)
Block(3,12,2,162:13)
Block(3,12,3,162:13)
Block(3,12,4,162:13)
Block(3,13,-10,162:13)
Block(3,13,2,162:13)
Block(3,13,3,162:13)
Block(3,13,4,162:13)
Block(3,14,-10,162:13)
Block(3,14,4,162:13)
Block(3,17,-6,162:13)
Block(3,17,-5,162:13)
Block(3,17,6,162:13)
Block(3,17,7,162:13)
Block(3,17,8,162:13)
Block(3,18,-6,162:13)
Block(3,18,-5,162:13)
Block(3,18,7,162:13)
Block(3,24,6,162:13)
Block(3,24,7,162:13)
Block(3,26,3,162:13)
Block(4,1,-6,162:13)
Block(4,1,-5,188)
Block(4,2,-6,162:13)
Block(4,2,-1,188)
Block(4,3,-1,188)
Block(4,4,-2,188)
Block(4,4,-1,188)
Block(4,4,2,162:13)
Block(4,5,-2,162:13)
Block(4,5,-1,162:13)
Block(4,5,0,162:13)
Block(4,5,1,162:13)
Block(4,5,2,162:13)
Block(4,5,3,162:13)
Block(4,6,-1,162:13)
Block(4,6,0,162:13)
Block(4,6,1,162:13)
Block(4,6,2,162:13)
Block(4,7,-1,162:13)
Block(4,7,0,162:13)
Block(4,7,1,162:13)
Block(4,7,2,188)
Block(4,8,-1,162:13)
Block(4,8,0,162:13)
Block(4,8,1,162:13)
Block(4,8,2,162:13)
Block(4,9,-1,162:13)
Block(4,9,0,162:13)
Block(4,9,1,162:13)
Block(4,9,2,162:13)
Block(4,10,1,162:13)
Block(4,10,2,162:13)
Block(4,10,3,162:13)
Block(4,11,1,162:13)
Block(4,11,2,162:13)
Block(4,11,3,162:13)
Block(4,12,2,162:13)
Block(4,12,3,162:13)
Block(4,12,4,162:13)
Block(4,13,3,162:13)
Block(4,13,4,162:13)
Block(4,13,5,162:13)
Block(4,14,3,162:13)
Block(4,14,4,162:13)
Block(4,14,5,162:13)
Block(4,15,-9,162:13)
Block(4,15,4,162:13)
Block(4,15,5,162:13)
Block(4,16,5,162:13)
Block(4,16,6,162:13)
Block(4,17,-8,162:13)
Block(4,17,-7,162:13)
Block(4,17,6,162:13)
Block(4,17,7,162:13)
Block(4,18,-7,162:13)
Block(4,18,-6,162:13)
Block(4,18,6,162:13)
Block(4,23,7,162:13)
Block(4,24,7,162:13)
Block(5,1,-6,162:13)
Block(5,3,3,162:13)
Block(5,3,4,188)
Block(5,4,0,188)
Block(5,4,2,162:13)
Block(5,4,3,162:13)
Block(5,5,-2,162:13)
Block(5,5,-1,162:13)
Block(5,5,0,162:13)
Block(5,5,1,162:13)
Block(5,5,2,162:13)
Block(5,5,3,188)
Block(5,6,-2,162:13)
Block(5,6,-1,162:13)
Block(5,6,0,162:13)
Block(5,6,1,162:13)
Block(5,6,2,188)
Block(5,7,-2,188)
Block(5,7,-1,162:13)
Block(5,7,0,162:13)
Block(5,7,1,162:13)
Block(5,8,-1,162:13)
Block(5,8,0,162:13)
Block(5,8,1,162:13)
Block(5,8,2,162:13)
Block(5,9,0,162:13)
Block(5,9,1,162:13)
Block(5,9,2,162:13)
Block(5,10,1,162:13)
Block(5,10,2,162:13)
Block(5,13,3,162:13)
Block(5,14,3,162:13)
Block(5,14,4,162:13)
Block(5,14,5,162:13)
Block(5,15,-9,162:13)
Block(5,15,4,162:13)
Block(5,15,5,162:13)
Block(5,15,6,162:13)
Block(5,16,-9,162:13)
Block(5,16,-8,162:13)
Block(5,16,4,162:13)
Block(5,16,5,162:13)
Block(5,16,6,162:13)
Block(5,17,-8,162:13)
Block(5,17,5,162:13)
Block(5,17,6,162:13)
Block(5,17,7,162:13)
Block(5,18,6,162:13)
Block(5,19,-6,162:13)
Block(5,22,7,162:13)
Block(5,23,7,162:13)
Block(6,1,4,188)
Block(6,1,5,188)
Block(6,2,4,162:13)
Block(6,2,5,162:13)
Block(6,3,3,162:13)
Block(6,3,4,162:13)
Block(6,5,-2,162:13)
Block(6,5,-1,188)
Block(6,6,-3,162:13)
Block(6,6,-2,162:13)
Block(6,6,-1,162:13)
Block(6,6,0,162:13)
Block(6,7,-1,188)
Block(6,7,0,162:13)
Block(6,7,1,162:13)
Block(6,8,1,162:13)
Block(6,15,4,162:13)
Block(6,15,5,162:13)
Block(6,16,-9,162:13)
Block(6,16,-8,162:13)
Block(6,16,4,162:13)
Block(6,16,5,162:13)
Block(6,16,6,162:13)
Block(6,16,12,162:13)
Block(6,17,5,162:13)
Block(6,17,6,162:13)
Block(6,18,6,162:13)
Block(6,19,-6,162:13)
Block(6,22,7,162:13)
Block(7,5,-3,162:13)
Block(7,5,-2,162:13)
Block(7,6,-2,162:13)
Block(7,6,-1,188)
Block(7,15,11,162:13)
Block(7,15,12,162:13)
Block(7,16,-9,162:13)
Block(7,16,7,162:13)
Block(7,17,5,162:13)
Block(7,17,6,162:13)
Block(7,17,7,162:13)
Block(7,18,5,162:13)
Block(7,18,6,162:13)
Block(7,18,7,162:13)
Block(7,20,-5,162:13)
Block(7,20,6,162:13)
Block(7,21,7,162:13)
Block(7,22,3,162:13)
Block(7,22,6,162:13)
Block(7,22,7,162:13)
Block(7,23,3,162:13)
Block(7,23,4,162:13)
Block(7,23,5,162:13)
Block(7,23,6,162:13)
Block(8,3,-1,188)
Block(8,4,-2,162:13)
Block(8,4,-1,188)
Block(8,5,-3,162:13)
Block(8,5,-2,162:13)
Block(8,14,9,162:13)
Block(8,14,10,162:13)
Block(8,14,11,162:13)
Block(8,15,8,162:13)
Block(8,15,9,162:13)
Block(8,15,11,162:13)
Block(8,16,-9,162:13)
Block(8,16,7,162:13)
Block(8,16,8,162:13)
Block(8,17,7,162:13)
Block(8,18,5,162:13)
Block(8,18,6,162:13)
Block(8,19,6,162:13)
Block(8,20,6,162:13)
Block(8,20,7,162:13)
Block(8,21,2,162:13)
Block(8,21,7,162:13)
Block(8,21,8,162:13)
Block(8,22,2,162:13)
Block(8,22,3,162:13)
Block(8,22,8,162:13)
Block(8,22,9,162:13)
Block(8,23,9,162:13)
Block(9,3,-2,188)
Block(9,3,-1,162:13)
Block(9,4,-2,162:13)
Block(9,4,-1,162:13)
Block(9,15,-9,162:13)
Block(9,19,6,162:13)
Block(9,20,1,162:13)
Block(9,20,6,162:13)
Block(9,21,1,162:13)
Block(9,21,2,162:13)
Block(9,22,0,162:13)
Block(9,23,9,162:13)
Block(9,24,9,162:13)
Block(9,24,10,162:13)
Block(10,1,0,188)
Block(10,2,0,162:13)
Block(10,3,-1,162:13)
Block(10,3,0,162:13)
Block(10,4,-1,162:13)
Block(10,14,-10,162:13)
Block(10,19,1,162:13)
Block(10,22,0,162:13)
Block(10,23,-1,162:13)
Block(10,24,10,162:13)
Block(10,25,10,162:13)
Block(11,1,0,188)
Block(11,2,0,162:13)
Block(11,2,1,188)
Block(11,13,-10,162:13)
Block(11,13,-9,162:13)
Block(11,19,1,162:13)
Block(11,23,-2,162:13)
Block(11,25,9,162:13)
Block(11,25,10,162:13)
Block(12,13,-9,162:13)
Block(12,13,-8,162:13)
Block(12,18,2,162:13)
Block(12,25,9,162:13)


#######################################################################
# +-----------------------------------------------------------------+ #
# |                             Entities                            | #
# +-----------------------------------------------------------------+ #
#######################################################################

# Entity() spawns an entity instead of a block. The entity is spawned only once when the BO3 is spawned.
# Entities are persistent by default so they don't de-spawn when no player is near, they are only unloaded.
# Usage: Entity(x,y,z,mobName,groupSize,NameTagOrNBTFileName) or Entity(x,y,z,mobName,groupSize)
# Use /tc entities or /otg entities to get a list of entities that can be used as mobName, this includes entities added by other mods.
# NameTagOrNBTFileName can be either a nametag for the mob or an nbt file (such as mymobinfo.nbt or mymobinfo.txt).
# When using a text file you can use the same mob spawning parameters used with the /summon command to equip the
# entity and give it custom attributes etc. You can copy the DATA part of a summon command including surrounding
# curly braces to a .txt file, for instance for: "/summon Skeleton x y z {DATA}"

#######################################################################
# +-----------------------------------------------------------------+ #
# |                            BO3 checks                           | #
# +-----------------------------------------------------------------+ #
#######################################################################

# Require a condition at a certain location in order for the BO3 to be spawned.
# BlockCheck(x,y,z,BlockName[,BlockName[,...]]) - one of the blocks must be at the location
# BlockCheckNot(x,y,z,BlockName[,BlockName[,...]]) - all the blocks must not be at the location
# LightCheck(x,y,z,minLightLevel,maxLightLevel) - light must be between min and max (inclusive)

# You can use "Solid" as a BlockName for matching all solid blocks or "All" to match all blocks that aren't air.

# Examples:
#   BlockCheck(0,-1,0,GRASS,DIRT)  Require grass or dirt just below the object
#   BlockCheck(0,-1,0,Solid)       Require any solid block just below the object
#   BlockCheck(0,-1,0,WOOL)        Require any type of wool just below the object
#   BlockCheck(0,-1,0,WOOL:0)      Require white wool just below the object
#   BlockCheckNot(0,-1,0,WOOL:0)   Require that there is no white wool below the object
#   LightCheck(0,0,0,0,1)          Require almost complete darkness just below the object
BlockCheck(0,-1,0,SAND,GRASS,DIRT,GRAVEL)
