#######################################################################
# +-----------------------------------------------------------------+ #
# |                            BO3 object                           | #
# +-----------------------------------------------------------------+ #
#######################################################################

# The descriptions in this file are accurate only for TerrainControl and OTG.
# For MCW and OTG+ these descriptions are only accurate if the BO3 is used as a CustomObject.
# MCW and OTG+ completely reimplemented CustomStructure, check the MCW/OTG+ documentation for more information.

# This is the config file of a custom object.
# If you add this object correctly to your BiomeConfigs, it will spawn in the world.

# This is the creator of this BO3 object
Author: Unknown

# A short description of this BO3 object
Description: This BO3 was converted from a schematic using OTGEdit. The author and description information of the schematic could not be found. If you know who the author of the schematic is then please add this information.

# The BO3 version, don't change this! It can be used by external applications to do a version check.
Version: 3

# The settings mode, WriteAll, WriteWithoutComments or WriteDisable. See WorldConfig.
SettingsMode: WriteDisable

#######################################################################
# +-----------------------------------------------------------------+ #
# |                          Main settings                          | #
# +-----------------------------------------------------------------+ #
#######################################################################

# This needs to be set to true to spawn the object in the Tree and Sapling resources.
Tree: true

# The frequency of the BO3 from 1 to 200. Tries this many times to spawn this BO3 when using the CustomObject(...) resource.
# Ignored by Tree(..), Sapling(..) and CustomStructure(..)
Frequency: 1

# The rarity of the BO3 from 0 to 100. Each spawn attempt has rarity% chance to succeed when using the CustomObject(...) resource.
# Ignored by Tree(..), Sapling(..) and CustomStructure(..)
Rarity: 3

# If you set this to true, the BO3 will be placed with a random rotation.
RotateRandomly: true

# The spawn height of the BO3 - randomY, highestBlock or highestSolidBlock.
SpawnHeight: highestBlock

# The height limits for the BO3.
MinHeight: 0

MaxHeight: 256

# Objects can have other objects attached to it: branches. Branches can also
# have branches attached to it, which can also have branches, etc. This is the
# maximum branch depth for this objects.
MaxBranchDepth: 10

# When spawned with the UseWorld keyword, this BO3 should NOT spawn in the following biomes.
# If you writer.write the BO3 name directly in the BiomeConfigs, this will be ignored.
ExcludedBiomes: All

# To optimise this BO3 for faster loading times you can use Notepad++ to find/replace comments and abbreviate things.
# Notepad++ find/replace with regex:
# Find: ^[#;].* replace to nothing removes all lines starting with # 
# Find: ^\s*$ replace to nothing removes most empty lines 
# Notepad++ find/replace without regex:
# *Warning: This will only work for OTG 1.10.2 v21 / OTG 1.11.2 v6 or higher. B( is not recognised by lower versions.
# Find: Block( replace to B(

#######################################################################
# +-----------------------------------------------------------------+ #
# |                      Source block settings                      | #
# +-----------------------------------------------------------------+ #
#######################################################################

# The block(s) the BO3 should spawn in.
SourceBlocks: AIR

# The maximum percentage of the BO3 that can be outside the SourceBlock.
# The BO3 won't be placed on a location with more blocks outside the SourceBlock than this percentage.
MaxPercentageOutsideSourceBlock: 100

# What to do when a block is about to be placed outside the SourceBlock? (dontPlace, placeAnyway)
OutsideSourceBlock: placeAnyway

#######################################################################
# +-----------------------------------------------------------------+ #
# |                              Blocks                             | #
# +-----------------------------------------------------------------+ #
#######################################################################

# All the blocks used in the BO3 are listed here. Possible blocks:
# Block(x,y,z,id[.data][,nbtfile.nbt) or B(x,y,z,id[.data][,nbtfile.nbt)
# RandomBlock(x,y,z,id[:data][,nbtfile.nbt],chance[,id[:data][,nbtfile.nbt],chance[,...]])
# So RandomBlock(0,0,0,CHEST,chest.nbt,50,CHEST,anotherchest.nbt,100) will spawn a chest at
# the BO3 origin, and give it a 50% chance to have the contents of chest.nbt, or, if that
# fails, a 100% percent chance to have the contents of anotherchest.nbt.

Block(-16,9,-3,18)
Block(-16,10,-4,18)
Block(-16,10,-3,18)
Block(-16,11,-3,18)
Block(-15,5,-3,18)
Block(-15,6,-3,18)
Block(-15,7,-3,18)
Block(-15,8,-3,18)
Block(-15,9,-4,18)
Block(-15,9,-3,17:15)
Block(-15,10,-4,18)
Block(-15,10,-3,17:15)
Block(-15,10,-2,18)
Block(-15,11,-4,18)
Block(-15,11,-3,17:15)
Block(-15,11,-2,18)
Block(-15,11,1,18)
Block(-15,12,-3,18)
Block(-15,12,-2,18)
Block(-15,12,1,18)
Block(-15,13,-3,18)
Block(-15,13,1,18)
Block(-15,14,-3,18)
Block(-15,14,1,18)
Block(-15,15,-3,18)
Block(-15,15,-2,18)
Block(-15,15,0,18)
Block(-15,15,1,18)
Block(-15,15,2,18)
Block(-15,16,-3,18)
Block(-14,6,1,18)
Block(-14,7,1,18)
Block(-14,8,1,18)
Block(-14,9,-3,18)
Block(-14,9,1,18)
Block(-14,10,-3,18)
Block(-14,10,0,18)
Block(-14,10,1,18)
Block(-14,11,-3,18)
Block(-14,11,-2,18)
Block(-14,11,0,18)
Block(-14,11,1,18)
Block(-14,12,-3,17:15)
Block(-14,12,-2,18)
Block(-14,12,0,18)
Block(-14,12,1,17:15)
Block(-14,12,2,18)
Block(-14,13,-3,17:15)
Block(-14,13,-2,18)
Block(-14,13,0,18)
Block(-14,13,1,17:15)
Block(-14,13,2,18)
Block(-14,14,-3,17:15)
Block(-14,14,-2,18)
Block(-14,14,0,18)
Block(-14,14,1,17:15)
Block(-14,14,2,18)
Block(-14,15,-4,18)
Block(-14,15,-3,17:15)
Block(-14,15,-2,18)
Block(-14,15,1,17:15)
Block(-14,15,2,18)
Block(-14,16,-4,18)
Block(-14,16,-3,18)
Block(-14,16,1,17:15)
Block(-14,16,2,18)
Block(-14,17,0,18)
Block(-14,17,1,18)
Block(-14,17,2,18)
Block(-13,7,-8,18)
Block(-13,8,-8,18)
Block(-13,9,-8,18)
Block(-13,10,-8,18)
Block(-13,11,-9,18)
Block(-13,11,-8,18)
Block(-13,12,-3,18)
Block(-13,13,-3,18)
Block(-13,13,-2,18)
Block(-13,15,-3,17:15)
Block(-13,15,0,18)
Block(-13,15,1,17:15)
Block(-13,16,-3,17:15)
Block(-13,16,0,17:15)
Block(-13,16,1,17:15)
Block(-13,16,2,18)
Block(-13,17,-2,18)
Block(-13,17,-1,18)
Block(-13,17,0,17:15)
Block(-13,17,1,18)
Block(-13,18,0,18)
Block(-13,18,1,18)
Block(-12,3,-8,18)
Block(-12,4,-8,18)
Block(-12,5,-8,18)
Block(-12,6,-8,18)
Block(-12,7,-9,18)
Block(-12,7,-8,17:15)
Block(-12,8,-9,18)
Block(-12,8,-8,17:15)
Block(-12,8,-7,18)
Block(-12,8,2,18)
Block(-12,9,-9,18)
Block(-12,9,-8,17:15)
Block(-12,9,-7,18)
Block(-12,9,2,18)
Block(-12,10,-8,17:15)
Block(-12,10,-7,18)
Block(-12,10,2,18)
Block(-12,11,-9,18)
Block(-12,11,-8,17:15)
Block(-12,11,-6,18)
Block(-12,12,-9,18)
Block(-12,12,-8,18)
Block(-12,12,-6,18)
Block(-12,12,2,18)
Block(-12,13,-8,18)
Block(-12,13,-6,18)
Block(-12,13,2,18)
Block(-12,14,-6,18)
Block(-12,14,3,18)
Block(-12,15,-9,18)
Block(-12,15,-8,18)
Block(-12,15,2,18)
Block(-12,16,-3,17:15)
Block(-12,16,-2,17:15)
Block(-12,16,0,18)
Block(-12,16,1,17:15)
Block(-12,17,-7,18)
Block(-12,17,-6,18)
Block(-12,17,-4,18)
Block(-12,17,-3,17:15)
Block(-12,17,-2,17:15)
Block(-12,17,-1,18)
Block(-12,17,0,17:15)
Block(-12,17,1,17:15)
Block(-12,18,-7,18)
Block(-12,18,-3,18)
Block(-12,18,-2,18)
Block(-12,18,-1,17:15)
Block(-12,18,0,17:15)
Block(-12,18,1,18)
Block(-12,19,-2,18)
Block(-12,19,-1,18)
Block(-12,19,0,18)
Block(-11,4,2,18)
Block(-11,5,2,18)
Block(-11,6,2,18)
Block(-11,7,2,18)
Block(-11,8,1,18)
Block(-11,8,2,17:15)
Block(-11,8,3,18)
Block(-11,9,-9,18)
Block(-11,9,-3,18)
Block(-11,9,1,18)
Block(-11,9,2,17:15)
Block(-11,10,-3,18)
Block(-11,10,1,18)
Block(-11,10,2,17:15)
Block(-11,10,3,18)
Block(-11,11,-9,18)
Block(-11,11,-8,18)
Block(-11,11,-7,18)
Block(-11,11,-3,18)
Block(-11,11,1,18)
Block(-11,11,2,17:15)
Block(-11,11,3,18)
Block(-11,12,-9,18)
Block(-11,12,-8,17:15)
Block(-11,12,-3,18)
Block(-11,12,1,18)
Block(-11,12,2,17:15)
Block(-11,13,-9,18)
Block(-11,13,-8,17:15)
Block(-11,13,-6,18)
Block(-11,13,-3,18)
Block(-11,13,1,18)
Block(-11,13,2,17:15)
Block(-11,13,3,18)
Block(-11,14,-9,18)
Block(-11,14,-8,17:15)
Block(-11,14,-7,18)
Block(-11,14,-6,18)
Block(-11,14,-3,18)
Block(-11,14,0,18)
Block(-11,14,1,17:15)
Block(-11,14,2,18)
Block(-11,14,3,18)
Block(-11,15,-9,18)
Block(-11,15,-8,17:15)
Block(-11,15,-7,17:15)
Block(-11,15,-6,18)
Block(-11,15,-3,18)
Block(-11,15,0,18)
Block(-11,15,1,17:15)
Block(-11,15,2,18)
Block(-11,16,-8,18)
Block(-11,16,-7,17:15)
Block(-11,16,-6,18)
Block(-11,16,-3,18)
Block(-11,16,-1,18)
Block(-11,16,0,18)
Block(-11,16,1,17:15)
Block(-11,17,-8,18)
Block(-11,17,-7,17:15)
Block(-11,17,-6,18)
Block(-11,17,-3,17:15)
Block(-11,17,-2,17:15)
Block(-11,17,-1,18)
Block(-11,17,0,18)
Block(-11,17,1,18)
Block(-11,17,2,18)
Block(-11,18,-6,18)
Block(-11,18,-3,18)
Block(-11,18,-2,17:15)
Block(-11,18,-1,17:15)
Block(-11,18,0,18)
Block(-11,19,-2,18)
Block(-11,19,-1,18)
Block(-10,9,2,18)
Block(-10,9,3,18)
Block(-10,10,2,18)
Block(-10,12,-8,18)
Block(-10,13,-1,18)
Block(-10,13,3,18)
Block(-10,14,-8,18)
Block(-10,14,0,18)
Block(-10,14,1,18)
Block(-10,14,2,18)
Block(-10,15,-8,18)
Block(-10,15,-5,18)
Block(-10,15,-2,18)
Block(-10,15,0,18)
Block(-10,15,1,18)
Block(-10,16,-8,17:15)
Block(-10,16,-7,17:15)
Block(-10,16,-6,18)
Block(-10,16,-5,18)
Block(-10,16,-4,18)
Block(-10,16,-2,18)
Block(-10,16,-1,18)
Block(-10,16,0,18)
Block(-10,17,-8,18)
Block(-10,17,-7,17:15)
Block(-10,17,-6,17:15)
Block(-10,17,-5,17:15)
Block(-10,17,-4,17:15)
Block(-10,17,-3,17:15)
Block(-10,17,-2,17:15)
Block(-10,17,1,18)
Block(-10,18,-7,18)
Block(-10,18,-5,18)
Block(-10,18,-4,18)
Block(-10,18,-3,17:15)
Block(-10,18,-2,17:15)
Block(-10,18,-1,17:15)
Block(-10,19,-4,18)
Block(-10,19,-3,18)
Block(-10,19,-2,18)
Block(-9,5,1,18)
Block(-9,6,1,18)
Block(-9,7,1,18)
Block(-9,8,-9,18)
Block(-9,8,1,18)
Block(-9,9,-9,18)
Block(-9,9,0,18)
Block(-9,9,1,17:15)
Block(-9,10,-9,18)
Block(-9,10,0,18)
Block(-9,10,1,17:15)
Block(-9,10,2,18)
Block(-9,10,3,18)
Block(-9,11,-7,18)
Block(-9,11,0,18)
Block(-9,11,1,17:15)
Block(-9,11,2,18)
Block(-9,12,-8,18)
Block(-9,12,0,17:15)
Block(-9,12,1,17:15)
Block(-9,13,-8,18)
Block(-9,13,-7,18)
Block(-9,13,0,17:15)
Block(-9,13,1,17:15)
Block(-9,14,-8,18)
Block(-9,14,-3,18)
Block(-9,14,-1,18)
Block(-9,14,0,17:15)
Block(-9,15,-8,18)
Block(-9,15,-7,18)
Block(-9,15,-6,18)
Block(-9,15,-5,18)
Block(-9,15,-3,18)
Block(-9,15,-2,18)
Block(-9,15,-1,18)
Block(-9,15,0,17:15)
Block(-9,15,1,18)
Block(-9,16,-8,18)
Block(-9,16,-7,17:15)
Block(-9,16,-6,18)
Block(-9,16,-5,18)
Block(-9,16,-4,17:15)
Block(-9,16,-3,18)
Block(-9,16,-1,17:15)
Block(-9,16,0,17:15)
Block(-9,17,-8,18)
Block(-9,17,-7,17:15)
Block(-9,17,-6,17:15)
Block(-9,17,-5,17:15)
Block(-9,17,-4,17:15)
Block(-9,17,-3,17:15)
Block(-9,17,-2,17:15)
Block(-9,17,-1,17:15)
Block(-9,17,1,18)
Block(-9,18,-7,18)
Block(-9,18,-5,18)
Block(-9,18,-3,17:15)
Block(-9,18,-2,17:15)
Block(-9,18,-1,18)
Block(-9,19,-3,18)
Block(-8,4,-9,18)
Block(-8,5,-9,18)
Block(-8,6,-9,18)
Block(-8,7,-9,18)
Block(-8,8,-9,17:15)
Block(-8,9,-10,18)
Block(-8,9,-9,17:15)
Block(-8,10,-10,18)
Block(-8,10,-9,17:15)
Block(-8,10,-8,18)
Block(-8,11,-10,18)
Block(-8,11,-9,17:15)
Block(-8,11,-8,18)
Block(-8,11,-7,18)
Block(-8,12,-9,18)
Block(-8,12,-8,17:15)
Block(-8,12,-7,18)
Block(-8,12,1,18)
Block(-8,13,-9,18)
Block(-8,13,-8,17:15)
Block(-8,13,-7,18)
Block(-8,14,-8,17:15)
Block(-8,14,-3,18)
Block(-8,14,-2,18)
Block(-8,15,-9,18)
Block(-8,15,-8,17:15)
Block(-8,15,-7,18)
Block(-8,15,-4,17:15)
Block(-8,15,-3,17:15)
Block(-8,15,-1,18)
Block(-8,16,-8,17:15)
Block(-8,16,-7,17:15)
Block(-8,16,-6,18)
Block(-8,16,-4,17:15)
Block(-8,16,-3,17:15)
Block(-8,16,-2,18)
Block(-8,16,-1,18)
Block(-8,16,0,18)
Block(-8,17,-8,18)
Block(-8,17,-7,17:15)
Block(-8,17,-5,18)
Block(-8,17,-4,18)
Block(-8,17,-3,17:15)
Block(-8,18,-7,18)
Block(-8,18,-4,18)
Block(-8,18,-2,18)
Block(-8,19,-2,18)
Block(-7,10,-9,18)
Block(-7,12,-9,18)
Block(-7,13,-8,18)
Block(-7,14,-9,18)
Block(-7,14,-8,18)
Block(-7,14,-3,18)
Block(-7,15,-8,18)
Block(-7,15,-7,18)
Block(-7,15,-5,18)
Block(-7,15,-4,17:15)
Block(-7,15,-3,18)
Block(-7,16,-8,18)
Block(-7,16,-7,18)
Block(-7,16,-5,18)
Block(-7,16,-4,17:15)
Block(-7,16,-3,18)
Block(-7,16,-2,18)
Block(-7,17,-7,18)
Block(-7,17,-5,18)
Block(-7,17,-4,18)
Block(-6,0,2,190)
Block(-6,15,-4,17:15)
Block(-6,15,-3,17:15)
Block(-6,15,-2,18)
Block(-6,16,-5,18)
Block(-6,16,-4,18)
Block(-6,16,-3,18)
Block(-6,17,-5,18)
Block(-6,17,-4,18)
Block(-6,17,-3,18)
Block(-5,0,2,17:15)
Block(-5,13,-4,17:15)
Block(-5,13,-3,17:15)
Block(-5,14,-4,17:15)
Block(-5,14,-3,17:15)
Block(-5,14,-2,18)
Block(-5,15,-4,17:15)
Block(-5,15,-3,17:15)
Block(-5,15,-2,18)
Block(-5,16,-4,18)
Block(-4,0,-4,190)
Block(-4,0,-3,190)
Block(-4,0,2,17:15)
Block(-4,1,-7,17:15)
Block(-4,2,-6,190)
Block(-4,8,-1,17:15)
Block(-4,8,8,18)
Block(-4,9,-2,17:15)
Block(-4,9,-1,17:15)
Block(-4,9,8,18)
Block(-4,10,-2,17:15)
Block(-4,10,-1,17:15)
Block(-4,10,8,18)
Block(-4,10,9,18)
Block(-4,11,-3,17:15)
Block(-4,11,-2,17:15)
Block(-4,11,1,17:15)
Block(-4,12,-3,17:15)
Block(-4,12,-2,17:15)
Block(-4,12,1,17:15)
Block(-4,12,2,17:15)
Block(-4,12,8,18)
Block(-4,13,-3,17:15)
Block(-4,13,-2,17:15)
Block(-4,13,2,17:15)
Block(-4,13,3,17:15)
Block(-4,14,-4,18)
Block(-4,14,-3,18)
Block(-4,14,3,17:15)
Block(-4,14,8,18)
Block(-4,14,9,18)
Block(-4,15,-4,18)
Block(-4,15,-3,18)
Block(-4,15,-2,18)
Block(-4,15,1,18)
Block(-4,15,2,18)
Block(-4,15,3,18)
Block(-4,16,-4,18)
Block(-4,16,-2,18)
Block(-3,0,-8,17:15)
Block(-3,0,-7,17:15)
Block(-3,0,-3,17:15)
Block(-3,0,1,17:15)
Block(-3,0,2,17:15)
Block(-3,1,-7,17:15)
Block(-3,1,-6,17:15)
Block(-3,1,1,190)
Block(-3,2,-7,17:15)
Block(-3,2,-6,17:15)
Block(-3,2,-3,190)
Block(-3,3,-6,190)
Block(-3,3,-5,17:15)
Block(-3,5,8,18)
Block(-3,6,-2,17:15)
Block(-3,6,-1,17:15)
Block(-3,6,7,18)
Block(-3,6,8,18)
Block(-3,7,-1,17:15)
Block(-3,7,0,17:15)
Block(-3,7,7,18)
Block(-3,7,8,18)
Block(-3,8,-2,17:15)
Block(-3,8,-1,17:15)
Block(-3,8,0,17:15)
Block(-3,8,8,17:15)
Block(-3,8,9,18)
Block(-3,9,-2,17:15)
Block(-3,9,-1,17:15)
Block(-3,9,0,17:15)
Block(-3,9,7,18)
Block(-3,9,8,17:15)
Block(-3,9,9,18)
Block(-3,10,-2,17:15)
Block(-3,10,-1,17:15)
Block(-3,10,0,17:15)
Block(-3,10,1,17:15)
Block(-3,10,7,18)
Block(-3,10,8,17:15)
Block(-3,10,9,18)
Block(-3,10,10,18)
Block(-3,11,-2,17:15)
Block(-3,11,0,17:15)
Block(-3,11,1,17:15)
Block(-3,11,7,18)
Block(-3,11,8,17:15)
Block(-3,12,-5,18)
Block(-3,12,-3,17:15)
Block(-3,12,-2,17:15)
Block(-3,12,1,17:15)
Block(-3,12,2,17:15)
Block(-3,12,8,17:15)
Block(-3,12,9,18)
Block(-3,13,-5,18)
Block(-3,13,-4,18)
Block(-3,13,0,18)
Block(-3,13,1,17:15)
Block(-3,13,2,17:15)
Block(-3,13,8,17:15)
Block(-3,13,9,18)
Block(-3,14,-4,18)
Block(-3,14,1,18)
Block(-3,14,2,17:15)
Block(-3,14,3,17:15)
Block(-3,14,4,17:15)
Block(-3,14,7,18)
Block(-3,14,8,17:15)
Block(-3,14,9,18)
Block(-3,15,-3,18)
Block(-3,15,-2,18)
Block(-3,15,0,18)
Block(-3,15,1,18)
Block(-3,15,2,17:15)
Block(-3,15,3,17:15)
Block(-3,15,4,17:15)
Block(-3,16,2,18)
Block(-3,16,3,18)
Block(-3,16,4,17:15)
Block(-3,16,5,18)
Block(-3,16,6,18)
Block(-3,16,7,18)
Block(-3,17,3,18)
Block(-3,17,4,18)
Block(-2,0,-8,190)
Block(-2,0,-3,17:15)
Block(-2,0,1,17:15)
Block(-2,1,-7,17:15)
Block(-2,1,-6,17:15)
Block(-2,1,-3,17:15)
Block(-2,1,-2,17:15)
Block(-2,1,0,190)
Block(-2,1,1,17:15)
Block(-2,2,-7,17:15)
Block(-2,2,-6,17:15)
Block(-2,2,-5,17:15)
Block(-2,2,-4,17:15)
Block(-2,2,-3,17:15)
Block(-2,3,-6,17:15)
Block(-2,3,-5,17:15)
Block(-2,3,-4,17:15)
Block(-2,3,-3,17:15)
Block(-2,3,-2,17:15)
Block(-2,4,-4,190)
Block(-2,4,-3,17:15)
Block(-2,4,-2,17:15)
Block(-2,4,-1,17:15)
Block(-2,5,-3,17:15)
Block(-2,5,-2,17:15)
Block(-2,5,-1,17:15)
Block(-2,6,-3,17:15)
Block(-2,6,-2,17:15)
Block(-2,6,-1,17:15)
Block(-2,6,12,18)
Block(-2,7,-3,17:15)
Block(-2,7,-2,17:15)
Block(-2,7,-1,17:15)
Block(-2,7,12,18)
Block(-2,8,-9,18)
Block(-2,8,-2,17:15)
Block(-2,8,-1,17:15)
Block(-2,8,12,18)
Block(-2,8,13,18)
Block(-2,9,-9,18)
Block(-2,9,-1,17:15)
Block(-2,9,0,17:15)
Block(-2,9,8,18)
Block(-2,9,12,18)
Block(-2,10,-9,18)
Block(-2,10,-5,18)
Block(-2,10,-1,17:15)
Block(-2,10,0,17:15)
Block(-2,10,8,18)
Block(-2,10,11,18)
Block(-2,10,12,18)
Block(-2,11,-9,18)
Block(-2,11,-5,18)
Block(-2,11,1,17:15)
Block(-2,11,7,18)
Block(-2,11,8,18)
Block(-2,11,11,18)
Block(-2,12,-10,18)
Block(-2,12,-5,18)
Block(-2,12,1,17:15)
Block(-2,12,7,18)
Block(-2,12,12,18)
Block(-2,13,-10,18)
Block(-2,13,-9,18)
Block(-2,13,-5,18)
Block(-2,13,0,18)
Block(-2,13,1,18)
Block(-2,13,7,18)
Block(-2,13,10,18)
Block(-2,14,0,18)
Block(-2,14,1,18)
Block(-2,14,2,18)
Block(-2,14,7,17:15)
Block(-2,14,8,17:15)
Block(-2,14,9,18)
Block(-2,15,-4,18)
Block(-2,15,-3,18)
Block(-2,15,0,18)
Block(-2,15,1,18)
Block(-2,15,2,18)
Block(-2,15,3,17:15)
Block(-2,15,4,17:15)
Block(-2,15,5,17:15)
Block(-2,15,6,17:15)
Block(-2,15,7,17:15)
Block(-2,15,8,18)
Block(-2,16,3,17:15)
Block(-2,16,4,17:15)
Block(-2,16,5,17:15)
Block(-2,16,6,17:15)
Block(-2,16,7,18)
Block(-2,17,3,18)
Block(-2,17,4,18)
Block(-2,17,5,18)
Block(-2,17,6,18)
Block(-1,0,-8,190)
Block(-1,0,-7,190)
Block(-1,0,0,17:15)
Block(-1,0,1,17:15)
Block(-1,1,-3,190)
Block(-1,1,0,17:15)
Block(-1,1,1,17:15)
Block(-1,2,-6,17:15)
Block(-1,2,-5,17:15)
Block(-1,2,-4,17:15)
Block(-1,2,-3,17:15)
Block(-1,2,-2,17:15)
Block(-1,2,0,17:15)
Block(-1,3,-5,17:15)
Block(-1,3,-4,17:15)
Block(-1,3,-3,17:15)
Block(-1,3,-2,17:15)
Block(-1,3,-1,17:15)
Block(-1,3,12,18)
Block(-1,4,-4,17:15)
Block(-1,4,-3,17:15)
Block(-1,4,-2,17:15)
Block(-1,4,-1,17:15)
Block(-1,4,12,18)
Block(-1,5,-9,18)
Block(-1,5,-4,17:15)
Block(-1,5,-1,17:15)
Block(-1,5,12,18)
Block(-1,6,-9,18)
Block(-1,6,-3,17:15)
Block(-1,6,-2,17:15)
Block(-1,6,-1,17:15)
Block(-1,6,0,17:15)
Block(-1,6,12,18)
Block(-1,7,-9,18)
Block(-1,7,-3,17:15)
Block(-1,7,-2,17:15)
Block(-1,7,-1,17:15)
Block(-1,7,0,17:15)
Block(-1,7,11,18)
Block(-1,7,12,17:15)
Block(-1,7,13,18)
Block(-1,8,-9,18)
Block(-1,8,-1,17:15)
Block(-1,8,11,18)
Block(-1,8,12,17:15)
Block(-1,8,13,18)
Block(-1,9,-10,18)
Block(-1,9,-9,17:15)
Block(-1,9,11,18)
Block(-1,9,12,17:15)
Block(-1,9,13,18)
Block(-1,10,-10,18)
Block(-1,10,-9,17:15)
Block(-1,10,-8,18)
Block(-1,10,-2,18)
Block(-1,10,11,18)
Block(-1,10,12,17:15)
Block(-1,10,13,18)
Block(-1,11,-10,18)
Block(-1,11,-9,17:15)
Block(-1,11,-8,18)
Block(-1,11,-2,18)
Block(-1,11,7,18)
Block(-1,11,11,17:15)
Block(-1,11,12,17:15)
Block(-1,12,-10,18)
Block(-1,12,-9,17:15)
Block(-1,12,-2,18)
Block(-1,12,7,18)
Block(-1,12,10,18)
Block(-1,12,11,17:15)
Block(-1,13,-10,18)
Block(-1,13,-9,17:15)
Block(-1,13,-8,18)
Block(-1,13,-4,18)
Block(-1,13,-2,18)
Block(-1,13,11,17:15)
Block(-1,13,12,18)
Block(-1,14,-10,18)
Block(-1,14,-9,18)
Block(-1,14,-4,18)
Block(-1,14,-2,18)
Block(-1,14,0,18)
Block(-1,14,6,18)
Block(-1,14,7,18)
Block(-1,14,11,18)
Block(-1,14,12,18)
Block(-1,15,-4,18)
Block(-1,15,0,18)
Block(-1,15,2,18)
Block(-1,15,3,18)
Block(-1,15,4,18)
Block(-1,15,5,18)
Block(-1,15,6,17:15)
Block(-1,15,7,17:15)
Block(-1,16,2,18)
Block(-1,16,3,18)
Block(-1,16,4,17:15)
Block(-1,16,5,17:15)
Block(-1,16,6,17:15)
Block(-1,16,7,17:15)
Block(-1,16,8,18)
Block(-1,17,4,18)
Block(-1,17,5,18)
Block(-1,17,6,18)
Block(-1,17,7,18)
Block(-1,18,4,18)
Block(0,1,-5,17:15)
Block(0,1,-4,17:15)
Block(0,1,0,17:15)
Block(0,2,-5,17:15)
Block(0,2,-4,17:15)
Block(0,2,-3,17:15)
Block(0,2,-2,17:15)
Block(0,2,-1,17:15)
Block(0,2,0,17:15)
Block(0,3,-5,17:15)
Block(0,3,-4,17:15)
Block(0,3,-3,17:15)
Block(0,3,-2,17:15)
Block(0,3,-1,17:15)
Block(0,3,0,17:15)
Block(0,4,-4,17:15)
Block(0,4,-3,17:15)
Block(0,4,-2,17:15)
Block(0,4,-1,17:15)
Block(0,4,0,190)
Block(0,5,-4,17:15)
Block(0,5,-3,17:15)
Block(0,5,-2,17:15)
Block(0,5,-1,17:15)
Block(0,6,-4,17:15)
Block(0,6,-3,17:15)
Block(0,6,-2,17:15)
Block(0,6,-1,17:15)
Block(0,6,6,18)
Block(0,7,-4,17:15)
Block(0,7,-3,17:15)
Block(0,7,-2,17:15)
Block(0,7,6,18)
Block(0,8,-4,17:15)
Block(0,8,-3,17:15)
Block(0,8,6,18)
Block(0,9,-4,17:15)
Block(0,9,6,18)
Block(0,10,6,18)
Block(0,10,10,18)
Block(0,11,-9,18)
Block(0,11,0,18)
Block(0,11,2,18)
Block(0,11,6,18)
Block(0,11,13,18)
Block(0,12,-9,18)
Block(0,12,0,18)
Block(0,12,2,18)
Block(0,12,6,18)
Block(0,12,11,18)
Block(0,13,-9,17:15)
Block(0,13,-8,18)
Block(0,13,0,18)
Block(0,13,2,18)
Block(0,13,6,18)
Block(0,13,10,18)
Block(0,13,11,17:15)
Block(0,13,12,18)
Block(0,14,-11,18)
Block(0,14,-10,18)
Block(0,14,-9,17:15)
Block(0,14,-8,18)
Block(0,14,-3,18)
Block(0,14,-2,18)
Block(0,14,0,18)
Block(0,14,2,18)
Block(0,14,6,18)
Block(0,14,10,17:15)
Block(0,14,11,17:15)
Block(0,15,-9,18)
Block(0,15,-3,18)
Block(0,15,2,18)
Block(0,15,5,18)
Block(0,15,6,18)
Block(0,15,7,18)
Block(0,15,8,18)
Block(0,15,9,18)
Block(0,15,10,18)
Block(0,16,4,18)
Block(0,16,5,18)
Block(0,16,6,17:15)
Block(0,16,7,17:15)
Block(0,16,8,18)
Block(0,16,9,18)
Block(0,17,4,18)
Block(1,0,-2,17:15)
Block(1,0,-1,17:15)
Block(1,1,-5,17:15)
Block(1,1,-4,17:15)
Block(1,1,-3,17:15)
Block(1,1,-2,17:15)
Block(1,2,-5,17:15)
Block(1,2,-4,17:15)
Block(1,2,-3,17:15)
Block(1,2,-2,17:15)
Block(1,2,-1,17:15)
Block(1,3,-5,17:15)
Block(1,3,-4,17:15)
Block(1,3,-3,17:15)
Block(1,3,-2,17:15)
Block(1,3,-1,17:15)
Block(1,4,-3,17:15)
Block(1,4,-2,17:15)
Block(1,4,-1,190)
Block(1,5,-3,17:15)
Block(1,5,-2,17:15)
Block(1,5,-1,17:15)
Block(1,6,-3,17:15)
Block(1,6,-2,17:15)
Block(1,6,-1,17:15)
Block(1,7,-4,17:15)
Block(1,7,-3,17:15)
Block(1,7,-2,17:15)
Block(1,7,12,18)
Block(1,8,-13,18)
Block(1,8,-4,17:15)
Block(1,8,-3,17:15)
Block(1,8,-2,17:15)
Block(1,8,12,18)
Block(1,9,-13,18)
Block(1,9,-4,17:15)
Block(1,9,-3,17:15)
Block(1,10,-13,18)
Block(1,10,-12,18)
Block(1,10,-4,17:15)
Block(1,10,-3,17:15)
Block(1,10,10,18)
Block(1,10,11,17:15)
Block(1,11,-13,18)
Block(1,11,-5,17:15)
Block(1,11,-4,17:15)
Block(1,11,10,18)
Block(1,11,11,17:15)
Block(1,12,-14,18)
Block(1,12,-13,18)
Block(1,12,-10,18)
Block(1,12,10,17:15)
Block(1,12,11,18)
Block(1,12,12,18)
Block(1,13,-12,18)
Block(1,13,-11,18)
Block(1,13,-10,18)
Block(1,13,-9,18)
Block(1,13,-8,18)
Block(1,13,9,18)
Block(1,13,10,18)
Block(1,13,11,18)
Block(1,14,-13,18)
Block(1,14,-11,18)
Block(1,14,-10,17:15)
Block(1,14,-9,17:15)
Block(1,14,-8,18)
Block(1,14,8,17:15)
Block(1,14,9,17:15)
Block(1,14,10,17:15)
Block(1,14,11,18)
Block(1,14,12,18)
Block(1,15,-11,18)
Block(1,15,-10,18)
Block(1,15,-9,18)
Block(1,15,-8,18)
Block(1,15,-4,18)
Block(1,15,-3,18)
Block(1,15,-1,18)
Block(1,15,6,17:15)
Block(1,15,7,17:15)
Block(1,15,8,17:15)
Block(1,15,9,17:15)
Block(1,16,-6,18)
Block(1,16,5,18)
Block(1,16,6,18)
Block(1,16,7,17:15)
Block(1,16,8,18)
Block(1,16,9,18)
Block(1,17,5,18)
Block(1,17,7,18)
Block(2,0,-4,190)
Block(2,0,-3,17:15)
Block(2,1,-5,190)
Block(2,1,-4,17:15)
Block(2,1,-3,190)
Block(2,2,-3,190)
Block(2,2,-1,190)
Block(2,3,-2,190)
Block(2,3,-1,190)
Block(2,3,13,18)
Block(2,4,-13,18)
Block(2,4,-2,17:15)
Block(2,4,13,18)
Block(2,5,-13,18)
Block(2,5,13,18)
Block(2,6,-13,18)
Block(2,6,12,18)
Block(2,6,13,18)
Block(2,7,-14,18)
Block(2,7,-13,18)
Block(2,7,-9,18)
Block(2,7,-3,17:15)
Block(2,7,-2,17:15)
Block(2,7,12,17:15)
Block(2,7,13,18)
Block(2,8,-14,18)
Block(2,8,-13,17:15)
Block(2,8,-9,18)
Block(2,8,-4,17:15)
Block(2,8,11,18)
Block(2,8,12,17:15)
Block(2,8,13,18)
Block(2,9,-14,18)
Block(2,9,-13,17:15)
Block(2,9,-12,18)
Block(2,9,-9,18)
Block(2,9,-4,17:15)
Block(2,9,-3,17:15)
Block(2,9,11,18)
Block(2,9,12,17:15)
Block(2,9,13,18)
Block(2,10,-14,18)
Block(2,10,-13,17:15)
Block(2,10,-12,18)
Block(2,10,-9,18)
Block(2,10,-5,17:15)
Block(2,10,-4,17:15)
Block(2,10,-3,17:15)
Block(2,10,9,18)
Block(2,10,10,18)
Block(2,10,11,17:15)
Block(2,10,12,17:15)
Block(2,11,-14,18)
Block(2,11,-13,17:15)
Block(2,11,-12,18)
Block(2,11,-10,18)
Block(2,11,-9,18)
Block(2,11,-4,17:15)
Block(2,11,-3,17:15)
Block(2,11,1,18)
Block(2,11,10,18)
Block(2,11,11,17:15)
Block(2,12,-14,18)
Block(2,12,-13,17:15)
Block(2,12,-12,18)
Block(2,12,-10,18)
Block(2,12,-4,17:15)
Block(2,12,-3,17:15)
Block(2,12,1,18)
Block(2,12,10,17:15)
Block(2,12,11,17:15)
Block(2,13,-14,18)
Block(2,13,-13,17:15)
Block(2,13,-10,18)
Block(2,13,-3,17:15)
Block(2,13,0,18)
Block(2,13,1,18)
Block(2,13,7,18)
Block(2,13,8,18)
Block(2,13,9,17:15)
Block(2,13,10,17:15)
Block(2,13,11,18)
Block(2,14,-14,18)
Block(2,14,-13,17:15)
Block(2,14,-12,18)
Block(2,14,-10,17:15)
Block(2,14,-9,18)
Block(2,14,-4,18)
Block(2,14,-3,18)
Block(2,14,-2,18)
Block(2,14,-1,18)
Block(2,14,0,18)
Block(2,14,6,17:15)
Block(2,14,7,18)
Block(2,14,8,17:15)
Block(2,14,9,17:15)
Block(2,14,10,18)
Block(2,15,-13,18)
Block(2,15,-12,18)
Block(2,15,-11,17:15)
Block(2,15,-10,17:15)
Block(2,15,-9,18)
Block(2,15,-4,18)
Block(2,15,-3,18)
Block(2,15,-2,18)
Block(2,15,-1,18)
Block(2,15,0,18)
Block(2,15,6,17:15)
Block(2,15,7,18)
Block(2,15,9,18)
Block(2,15,10,18)
Block(2,16,-12,18)
Block(2,16,-11,18)
Block(2,16,-10,18)
Block(2,16,-9,18)
Block(2,16,-7,18)
Block(2,16,-6,18)
Block(2,16,-5,18)
Block(2,16,-3,18)
Block(2,17,-11,18)
Block(2,17,-7,18)
Block(2,18,-11,18)
Block(2,18,-6,18)
Block(3,0,-4,17:15)
Block(3,0,-3,17:15)
Block(3,0,-2,17:15)
Block(3,1,-4,17:15)
Block(3,1,-3,17:15)
Block(3,7,12,18)
Block(3,8,12,18)
Block(3,9,12,18)
Block(3,10,-14,18)
Block(3,10,-13,18)
Block(3,10,12,18)
Block(3,11,-13,18)
Block(3,11,-3,17:15)
Block(3,11,5,18)
Block(3,11,10,18)
Block(3,11,11,18)
Block(3,12,-13,18)
Block(3,12,-3,17:15)
Block(3,12,-1,18)
Block(3,12,4,18)
Block(3,12,5,17:15)
Block(3,12,6,18)
Block(3,12,9,18)
Block(3,12,10,18)
Block(3,12,12,18)
Block(3,13,-14,18)
Block(3,13,-13,17:15)
Block(3,13,-12,18)
Block(3,13,-4,17:15)
Block(3,13,-3,17:15)
Block(3,13,-2,18)
Block(3,13,-1,18)
Block(3,13,5,17:15)
Block(3,13,6,17:15)
Block(3,13,9,17:15)
Block(3,13,10,18)
Block(3,14,-14,18)
Block(3,14,-13,17:15)
Block(3,14,-12,18)
Block(3,14,-5,18)
Block(3,14,-4,17:15)
Block(3,14,-3,18)
Block(3,14,-2,18)
Block(3,14,-1,18)
Block(3,14,5,18)
Block(3,14,6,17:15)
Block(3,14,7,18)
Block(3,14,8,18)
Block(3,14,9,17:15)
Block(3,14,10,18)
Block(3,15,-14,18)
Block(3,15,-13,17:15)
Block(3,15,-12,17:15)
Block(3,15,-11,17:15)
Block(3,15,-10,18)
Block(3,15,-7,18)
Block(3,15,-6,18)
Block(3,15,-5,17:15)
Block(3,15,-4,18)
Block(3,15,-3,18)
Block(3,15,6,18)
Block(3,15,8,18)
Block(3,15,10,18)
Block(3,16,-13,17:15)
Block(3,16,-12,17:15)
Block(3,16,-11,18)
Block(3,16,-10,18)
Block(3,16,-9,18)
Block(3,16,-7,18)
Block(3,16,-6,17:15)
Block(3,16,-5,17:15)
Block(3,16,-4,18)
Block(3,16,-3,18)
Block(3,17,-11,18)
Block(3,17,-10,18)
Block(3,17,-7,18)
Block(3,17,-6,18)
Block(3,17,-5,18)
Block(3,18,-11,18)
Block(3,18,-6,18)
Block(4,0,-3,17:15)
Block(4,0,-2,17:15)
Block(4,0,-1,17:15)
Block(4,4,5,18)
Block(4,5,5,18)
Block(4,6,5,18)
Block(4,7,5,18)
Block(4,8,4,18)
Block(4,8,5,17:15)
Block(4,8,8,18)
Block(4,9,-1,18)
Block(4,9,4,18)
Block(4,9,5,17:15)
Block(4,9,8,18)
Block(4,9,9,18)
Block(4,10,-1,18)
Block(4,10,4,18)
Block(4,10,5,17:15)
Block(4,10,8,18)
Block(4,10,9,17:15)
Block(4,11,-1,18)
Block(4,11,4,18)
Block(4,11,5,17:15)
Block(4,11,6,18)
Block(4,11,8,18)
Block(4,11,9,17:15)
Block(4,11,10,18)
Block(4,12,-3,17:15)
Block(4,12,-1,18)
Block(4,12,4,18)
Block(4,12,5,17:15)
Block(4,12,6,18)
Block(4,12,8,18)
Block(4,12,9,17:15)
Block(4,12,10,18)
Block(4,13,-13,18)
Block(4,13,-5,17:15)
Block(4,13,-4,17:15)
Block(4,13,-3,17:15)
Block(4,13,-1,18)
Block(4,13,6,18)
Block(4,13,8,18)
Block(4,13,9,17:15)
Block(4,13,10,18)
Block(4,14,-12,18)
Block(4,14,-11,18)
Block(4,14,-5,17:15)
Block(4,14,-4,17:15)
Block(4,14,-3,17:15)
Block(4,14,5,18)
Block(4,14,9,18)
Block(4,14,10,18)
Block(4,15,-14,18)
Block(4,15,-13,17:15)
Block(4,15,-12,17:15)
Block(4,15,-11,18)
Block(4,15,-8,18)
Block(4,15,-6,17:15)
Block(4,15,-5,17:15)
Block(4,15,-4,18)
Block(4,15,-3,18)
Block(4,15,11,18)
Block(4,16,-13,18)
Block(4,16,-12,17:15)
Block(4,16,-11,17:15)
Block(4,16,-10,17:15)
Block(4,16,-9,18)
Block(4,16,-8,18)
Block(4,16,-7,17:15)
Block(4,16,-6,17:15)
Block(4,16,-5,18)
Block(4,16,-4,18)
Block(4,16,-3,18)
Block(4,17,-12,18)
Block(4,17,-11,18)
Block(4,17,-10,18)
Block(4,17,-8,18)
Block(4,17,-6,17:15)
Block(4,17,-5,18)
Block(4,17,-3,18)
Block(4,18,-11,18)
Block(4,18,-10,18)
Block(4,18,-7,18)
Block(4,18,-5,18)
Block(5,4,8,18)
Block(5,5,8,18)
Block(5,6,8,18)
Block(5,7,8,18)
Block(5,8,5,18)
Block(5,8,7,18)
Block(5,8,8,17:15)
Block(5,9,-11,18)
Block(5,9,5,18)
Block(5,9,7,18)
Block(5,9,8,17:15)
Block(5,9,9,18)
Block(5,10,-13,18)
Block(5,10,-11,18)
Block(5,10,5,18)
Block(5,10,9,18)
Block(5,11,-13,18)
Block(5,11,-11,18)
Block(5,11,4,18)
Block(5,11,9,18)
Block(5,12,-13,18)
Block(5,12,-11,18)
Block(5,13,-13,18)
Block(5,13,-11,18)
Block(5,13,9,18)
Block(5,14,-14,18)
Block(5,14,-13,17:15)
Block(5,14,-11,18)
Block(5,14,-10,18)
Block(5,14,-5,18)
Block(5,14,10,18)
Block(5,15,-13,17:15)
Block(5,15,-12,18)
Block(5,15,-11,18)
Block(5,15,-10,18)
Block(5,15,-9,18)
Block(5,15,-8,18)
Block(5,15,-4,18)
Block(5,16,-13,18)
Block(5,16,-11,17:15)
Block(5,16,-10,17:15)
Block(5,16,-9,17:15)
Block(5,16,-8,17:15)
Block(5,16,-7,17:15)
Block(5,16,-6,17:15)
Block(5,16,-5,18)
Block(5,16,-4,18)
Block(5,17,-10,17:15)
Block(5,17,-9,18)
Block(5,17,-8,18)
Block(5,17,-7,17:15)
Block(5,17,-6,18)
Block(5,18,-7,18)
Block(6,5,-13,18)
Block(6,6,-13,18)
Block(6,7,-13,18)
Block(6,8,-14,18)
Block(6,8,-13,18)
Block(6,8,8,18)
Block(6,9,-14,18)
Block(6,9,-13,18)
Block(6,9,-8,18)
Block(6,9,8,18)
Block(6,10,-14,18)
Block(6,10,-13,17:15)
Block(6,10,-12,18)
Block(6,10,-8,18)
Block(6,11,-14,18)
Block(6,11,-13,17:15)
Block(6,11,-12,18)
Block(6,11,-8,18)
Block(6,12,-14,18)
Block(6,12,-13,17:15)
Block(6,12,-12,18)
Block(6,12,-8,18)
Block(6,13,-14,18)
Block(6,13,-13,17:15)
Block(6,13,-8,18)
Block(6,14,-13,17:15)
Block(6,14,-11,18)
Block(6,14,-10,18)
Block(6,14,-8,18)
Block(6,15,-14,18)
Block(6,15,-13,18)
Block(6,15,-11,18)
Block(6,15,-10,17:15)
Block(6,15,-9,17:15)
Block(6,15,-8,18)
Block(6,15,-7,18)
Block(6,15,-6,18)
Block(6,16,-11,18)
Block(6,16,-10,17:15)
Block(6,16,-9,17:15)
Block(6,16,-8,17:15)
Block(6,16,-7,17:15)
Block(6,16,-6,17:15)
Block(6,16,-5,17:15)
Block(6,16,-4,18)
Block(6,17,-11,18)
Block(6,17,-10,18)
Block(6,17,-9,17:15)
Block(6,17,-8,17:15)
Block(6,17,-7,18)
Block(6,18,-10,18)
Block(6,18,-9,18)
Block(7,10,-13,18)
Block(7,10,-10,18)
Block(7,11,-14,18)
Block(7,11,-10,18)
Block(7,12,-13,18)
Block(7,12,-10,18)
Block(7,12,-9,18)
Block(7,13,-10,18)
Block(7,14,-13,18)
Block(7,14,-12,18)
Block(7,14,-10,17:15)
Block(7,14,-9,18)
Block(7,14,-8,18)
Block(7,15,-11,18)
Block(7,15,-10,17:15)
Block(7,15,-9,18)
Block(7,15,-8,17:15)
Block(7,15,-7,18)
Block(7,15,-6,18)
Block(7,15,-5,17:15)
Block(7,15,-4,17:15)
Block(7,16,-11,18)
Block(7,16,-10,17:15)
Block(7,16,-9,18)
Block(7,16,-8,17:15)
Block(7,16,-7,17:15)
Block(7,16,-5,17:15)
Block(7,16,-4,17:15)
Block(7,16,-3,18)
Block(7,17,-10,18)
Block(7,17,-6,18)
Block(7,17,-5,18)
Block(7,17,-4,18)
Block(7,18,-9,18)
Block(8,3,0,18)
Block(8,4,0,18)
Block(8,5,0,18)
Block(8,6,-10,18)
Block(8,6,0,18)
Block(8,7,-10,18)
Block(8,7,0,18)
Block(8,8,-10,18)
Block(8,8,0,18)
Block(8,9,-10,17:15)
Block(8,9,-9,18)
Block(8,9,0,18)
Block(8,10,-11,18)
Block(8,10,-10,17:15)
Block(8,10,0,18)
Block(8,11,-10,17:15)
Block(8,11,-9,18)
Block(8,11,-8,18)
Block(8,11,-1,18)
Block(8,11,0,18)
Block(8,12,-11,18)
Block(8,12,-10,17:15)
Block(8,12,-9,18)
Block(8,12,-1,18)
Block(8,13,-10,17:15)
Block(8,13,-9,18)
Block(8,13,-1,18)
Block(8,14,-10,17:15)
Block(8,14,-9,18)
Block(8,14,-3,18)
Block(8,14,-2,18)
Block(8,14,-1,18)
Block(8,14,0,18)
Block(8,15,-10,18)
Block(8,15,-9,18)
Block(8,15,-8,18)
Block(8,15,-7,17:15)
Block(8,15,-6,18)
Block(8,15,-4,17:15)
Block(8,15,-3,17:15)
Block(8,15,-2,17:15)
Block(8,16,-8,18)
Block(8,16,-7,17:15)
Block(8,16,-6,17:15)
Block(8,16,-5,18)
Block(8,17,-7,18)
Block(8,17,-6,18)
Block(8,17,-5,18)
Block(9,6,0,18)
Block(9,7,0,18)
Block(9,8,-11,18)
Block(9,8,-6,18)
Block(9,8,0,17:15)
Block(9,8,1,18)
Block(9,9,-11,18)
Block(9,9,-10,18)
Block(9,9,-6,18)
Block(9,9,-1,18)
Block(9,9,0,17:15)
Block(9,9,1,18)
Block(9,10,-11,18)
Block(9,10,-6,18)
Block(9,10,0,17:15)
Block(9,10,1,18)
Block(9,11,-6,18)
Block(9,11,0,17:15)
Block(9,12,-11,18)
Block(9,12,-10,18)
Block(9,12,-6,18)
Block(9,12,-1,17:15)
Block(9,13,-10,18)
Block(9,13,-1,17:15)
Block(9,13,0,18)
Block(9,14,-7,18)
Block(9,14,-6,18)
Block(9,14,-2,17:15)
Block(9,14,-1,17:15)
Block(9,14,0,18)
Block(9,15,-7,17:15)
Block(9,15,-6,17:15)
Block(9,15,-3,18)
Block(9,15,-2,17:15)
Block(9,15,-1,18)
Block(9,15,0,18)
Block(9,16,-6,18)
Block(9,16,-2,18)
Block(9,16,-1,18)
Block(9,17,-6,18)
Block(10,8,0,18)
Block(10,10,0,18)
Block(10,10,1,18)
Block(10,11,0,18)
Block(10,12,-6,18)
Block(10,13,-6,17:15)
Block(10,13,0,18)
Block(10,14,-6,17:15)
Block(10,14,-1,18)
Block(10,15,-8,18)
Block(10,15,-7,17:15)
Block(10,15,-6,17:15)
Block(10,15,-5,18)
Block(10,15,-1,18)
Block(11,12,-5,18)
Block(11,13,-6,17:15)
Block(11,13,-5,17:15)
Block(11,14,-7,18)
Block(11,14,-6,17:15)
Block(11,14,-5,17:15)
Block(11,15,-9,18)
Block(11,15,-8,18)
Block(11,15,-7,17:15)
Block(11,15,-6,17:15)
Block(11,16,-8,18)
Block(11,16,-7,18)
Block(11,16,-6,18)
Block(12,5,-8,18)
Block(12,5,-3,18)
Block(12,6,-8,18)
Block(12,6,-3,18)
Block(12,7,-8,18)
Block(12,7,-3,18)
Block(12,8,-8,18)
Block(12,8,-3,18)
Block(12,9,-8,18)
Block(12,9,-3,18)
Block(12,10,-9,18)
Block(12,10,-8,18)
Block(12,10,-7,18)
Block(12,10,-3,18)
Block(12,11,-4,18)
Block(12,11,-3,18)
Block(12,11,-2,18)
Block(12,12,-7,18)
Block(12,12,-5,18)
Block(12,12,-4,17:15)
Block(12,12,-3,18)
Block(12,12,-2,18)
Block(12,13,-9,18)
Block(12,13,-8,18)
Block(12,13,-6,18)
Block(12,13,-5,17:15)
Block(12,13,-4,17:15)
Block(12,13,-3,18)
Block(12,14,-8,17:15)
Block(12,14,-6,17:15)
Block(12,14,-5,18)
Block(12,14,-4,18)
Block(12,15,-8,17:15)
Block(12,15,-7,17:15)
Block(12,15,-6,18)
Block(12,16,-8,18)
Block(12,16,-7,18)
Block(13,3,-3,18)
Block(13,4,-3,18)
Block(13,5,-3,18)
Block(13,6,-4,18)
Block(13,6,-3,17:15)
Block(13,7,-4,18)
Block(13,7,-3,17:15)
Block(13,7,-2,18)
Block(13,8,-8,18)
Block(13,8,-4,18)
Block(13,8,-3,17:15)
Block(13,9,-8,17:15)
Block(13,9,-7,18)
Block(13,9,-4,18)
Block(13,9,-3,17:15)
Block(13,9,-2,18)
Block(13,10,-8,17:15)
Block(13,10,-4,18)
Block(13,10,-3,17:15)
Block(13,10,-2,18)
Block(13,11,-9,18)
Block(13,11,-8,17:15)
Block(13,11,-7,18)
Block(13,11,-4,18)
Block(13,11,-3,17:15)
Block(13,11,-2,18)
Block(13,12,-9,18)
Block(13,12,-8,17:15)
Block(13,12,-7,18)
Block(13,12,-5,18)
Block(13,12,-4,17:15)
Block(13,12,-3,17:15)
Block(13,12,-2,18)
Block(13,13,-9,18)
Block(13,13,-8,17:15)
Block(13,13,-7,18)
Block(13,13,-5,18)
Block(13,13,-4,17:15)
Block(13,13,-2,18)
Block(13,14,-8,17:15)
Block(13,14,-7,18)
Block(13,14,-6,18)
Block(13,15,-8,18)
Block(13,15,-7,17:15)
Block(13,15,-6,18)
Block(13,16,-7,18)
Block(13,16,-6,18)
Block(14,7,-3,18)
Block(14,8,-3,18)
Block(14,9,-8,18)
Block(14,9,-3,18)
Block(14,10,-8,18)
Block(14,10,-3,18)
Block(14,11,-7,18)
Block(14,11,-3,18)
Block(14,11,-2,18)
Block(14,11,-1,18)
Block(14,12,-9,18)
Block(14,12,-8,18)
Block(14,12,-4,18)
Block(14,12,-3,18)
Block(14,12,-2,18)
Block(14,13,-9,18)
Block(14,13,-8,18)
Block(14,13,-3,18)
Block(14,13,-2,18)
Block(14,14,-8,18)
Block(14,14,-4,18)
Block(14,15,-8,18)
Block(14,15,-7,18)
Block(14,16,-7,18)
Block(15,11,-2,18)
Block(15,12,-2,18)
Block(15,12,-1,18)


#######################################################################
# +-----------------------------------------------------------------+ #
# |                             Entities                            | #
# +-----------------------------------------------------------------+ #
#######################################################################

# Entity() spawns an entity instead of a block. The entity is spawned only once when the BO3 is spawned.
# Entities are persistent by default so they don't de-spawn when no player is near, they are only unloaded.
# Usage: Entity(x,y,z,mobName,groupSize,NameTagOrNBTFileName) or Entity(x,y,z,mobName,groupSize)
# Use /tc entities or /otg entities to get a list of entities that can be used as mobName, this includes entities added by other mods.
# NameTagOrNBTFileName can be either a nametag for the mob or an nbt file (such as mymobinfo.nbt or mymobinfo.txt).
# When using a text file you can use the same mob spawning parameters used with the /summon command to equip the
# entity and give it custom attributes etc. You can copy the DATA part of a summon command including surrounding
# curly braces to a .txt file, for instance for: "/summon Skeleton x y z {DATA}"

#######################################################################
# +-----------------------------------------------------------------+ #
# |                            BO3 checks                           | #
# +-----------------------------------------------------------------+ #
#######################################################################

# Require a condition at a certain location in order for the BO3 to be spawned.
# BlockCheck(x,y,z,BlockName[,BlockName[,...]]) - one of the blocks must be at the location
# BlockCheckNot(x,y,z,BlockName[,BlockName[,...]]) - all the blocks must not be at the location
# LightCheck(x,y,z,minLightLevel,maxLightLevel) - light must be between min and max (inclusive)

# You can use "Solid" as a BlockName for matching all solid blocks or "All" to match all blocks that aren't air.

# Examples:
#   BlockCheck(0,-1,0,GRASS,DIRT)  Require grass or dirt just below the object
#   BlockCheck(0,-1,0,Solid)       Require any solid block just below the object
#   BlockCheck(0,-1,0,WOOL)        Require any type of wool just below the object
#   BlockCheck(0,-1,0,WOOL:0)      Require white wool just below the object
#   BlockCheckNot(0,-1,0,WOOL:0)   Require that there is no white wool below the object
#   LightCheck(0,0,0,0,1)          Require almost complete darkness just below the object
BlockCheck(0,-1,0,GRASS,DIRT)
