#######################################################################
# +-----------------------------------------------------------------+ #
# |                            BO3 object                           | #
# +-----------------------------------------------------------------+ #
#######################################################################

# The descriptions in this file are accurate only for TerrainControl and OTG.
# For MCW and OTG+ these descriptions are only accurate if the BO3 is used as a CustomObject.
# MCW and OTG+ completely reimplemented CustomStructure, check the MCW/OTG+ documentation for more information.

# This is the config file of a custom object.
# If you add this object correctly to your BiomeConfigs, it will spawn in the world.

# This is the creator of this BO3 object
Author: Unknown

# A short description of this BO3 object
Description: This BO3 was converted from a schematic using OTGEdit. The author and description information of the schematic could not be found. If you know who the author of the schematic is then please add this information.

# The BO3 version, don't change this! It can be used by external applications to do a version check.
Version: 3

# The settings mode, WriteAll, WriteWithoutComments or WriteDisable. See WorldConfig.
SettingsMode: WriteDisable

#######################################################################
# +-----------------------------------------------------------------+ #
# |                          Main settings                          | #
# +-----------------------------------------------------------------+ #
#######################################################################

# This needs to be set to true to spawn the object in the Tree and Sapling resources.
Tree: true

# The frequency of the BO3 from 1 to 200. Tries this many times to spawn this BO3 when using the CustomObject(...) resource.
# Ignored by Tree(..), Sapling(..) and CustomStructure(..)
Frequency: 5

# The rarity of the BO3 from 0 to 100. Each spawn attempt has rarity% chance to succeed when using the CustomObject(...) resource.
# Ignored by Tree(..), Sapling(..) and CustomStructure(..)
Rarity: 15

# If you set this to true, the BO3 will be placed with a random rotation.
RotateRandomly: true

# The spawn height of the BO3 - randomY, highestBlock or highestSolidBlock.
SpawnHeight: highestBlock

# The height limits for the BO3.
MinHeight: 0

MaxHeight: 256

# Objects can have other objects attached to it: branches. Branches can also
# have branches attached to it, which can also have branches, etc. This is the
# maximum branch depth for this objects.
MaxBranchDepth: 10

# When spawned with the UseWorld keyword, this BO3 should NOT spawn in the following biomes.
# If you writer.write the BO3 name directly in the BiomeConfigs, this will be ignored.
ExcludedBiomes: All

# To optimise this BO3 for faster loading times you can use Notepad++ to find/replace comments and abbreviate things.
# Notepad++ find/replace with regex:
# Find: ^[#;].* replace to nothing removes all lines starting with # 
# Find: ^\s*$ replace to nothing removes most empty lines 
# Notepad++ find/replace without regex:
# *Warning: This will only work for OTG 1.10.2 v21 / OTG 1.11.2 v6 or higher. B( is not recognised by lower versions.
# Find: Block( replace to B(

#######################################################################
# +-----------------------------------------------------------------+ #
# |                      Source block settings                      | #
# +-----------------------------------------------------------------+ #
#######################################################################

# The block(s) the BO3 should spawn in.
SourceBlocks: AIR

# The maximum percentage of the BO3 that can be outside the SourceBlock.
# The BO3 won't be placed on a location with more blocks outside the SourceBlock than this percentage.
MaxPercentageOutsideSourceBlock: 100

# What to do when a block is about to be placed outside the SourceBlock? (dontPlace, placeAnyway)
OutsideSourceBlock: placeAnyway

#######################################################################
# +-----------------------------------------------------------------+ #
# |                              Blocks                             | #
# +-----------------------------------------------------------------+ #
#######################################################################

# All the blocks used in the BO3 are listed here. Possible blocks:
# Block(x,y,z,id[.data][,nbtfile.nbt) or B(x,y,z,id[.data][,nbtfile.nbt)
# RandomBlock(x,y,z,id[:data][,nbtfile.nbt],chance[,id[:data][,nbtfile.nbt],chance[,...]])
# So RandomBlock(0,0,0,CHEST,chest.nbt,50,CHEST,anotherchest.nbt,100) will spawn a chest at
# the BO3 origin, and give it a 50% chance to have the contents of chest.nbt, or, if that
# fails, a 100% percent chance to have the contents of anotherchest.nbt.

Block(-4,2,12,18:2)
Block(-4,8,-10,18:2)
Block(-4,8,-9,18:2)
Block(-4,8,-8,18:2)
Block(-3,3,11,18:2)
Block(-3,3,12,18:2)
Block(-3,4,12,18:2)
Block(-3,7,-10,18:2)
Block(-3,7,-9,18:2)
Block(-3,7,-8,18:2)
Block(-3,7,13,18:2)
Block(-3,8,-11,18:2)
Block(-3,8,-10,18:2)
Block(-3,8,-9,18:2)
Block(-3,8,-8,18:2)
Block(-3,8,-7,18:2)
Block(-2,4,11,18:2)
Block(-2,5,11,18:2)
Block(-2,5,12,18:2)
Block(-2,6,12,18:2)
Block(-2,7,-10,18:2)
Block(-2,7,-9,18:2)
Block(-2,7,-8,18:2)
Block(-2,7,10,18:2)
Block(-2,8,-11,18:2)
Block(-2,8,-10,18:2)
Block(-2,8,-9,17:14)
Block(-2,8,-8,18:2)
Block(-2,8,-7,18:2)
Block(-2,8,12,18:2)
Block(-2,9,-10,18:2)
Block(-2,9,-9,18:2)
Block(-2,9,-8,18:2)
Block(-2,9,12,18:2)
Block(-2,12,-7,18:2)
Block(-2,12,-6,18:2)
Block(-2,12,-5,18:2)
Block(-2,15,-7,18:2)
Block(-2,15,-6,18:2)
Block(-2,15,-5,18:2)
Block(-1,0,-7,17:14)
Block(-1,0,12,17:14)
Block(-1,1,12,17:14)
Block(-1,4,10,18:2)
Block(-1,4,14,18:2)
Block(-1,5,11,18:2)
Block(-1,5,13,18:2)
Block(-1,6,-8,17:14)
Block(-1,6,11,18:2)
Block(-1,6,12,18:2)
Block(-1,6,13,18:2)
Block(-1,7,-10,18:2)
Block(-1,7,-8,17:14)
Block(-1,7,12,18:2)
Block(-1,8,-11,18:2)
Block(-1,8,-10,18:2)
Block(-1,8,-9,18:2)
Block(-1,8,-8,18:2)
Block(-1,8,-7,18:2)
Block(-1,8,11,18:2)
Block(-1,9,-9,18:2)
Block(-1,9,-8,18:2)
Block(-1,9,-6,18:2)
Block(-1,9,-5,18:2)
Block(-1,9,-4,18:2)
Block(-1,9,12,18:2)
Block(-1,10,12,18:2)
Block(-1,11,-6,18:2)
Block(-1,11,11,18:2)
Block(-1,11,13,18:2)
Block(-1,12,-7,18:2)
Block(-1,12,-6,17:14)
Block(-1,12,-5,18:2)
Block(-1,13,-6,18:2)
Block(-1,13,13,18:2)
Block(-1,14,-7,18:2)
Block(-1,14,-6,18:2)
Block(-1,15,-8,18:2)
Block(-1,15,-7,18:2)
Block(-1,15,-6,18:2)
Block(-1,15,-5,18:2)
Block(-1,15,-4,18:2)
Block(-1,16,-7,18:2)
Block(-1,16,-6,18:2)
Block(-1,16,-5,18:2)
Block(0,0,-7,17:14)
Block(0,0,-6,17:14)
Block(0,0,10,17:14)
Block(0,0,11,17:14)
Block(0,0,12,17:14)
Block(0,0,13,17:14)
Block(0,1,-7,17:14)
Block(0,1,-6,17:14)
Block(0,1,11,17:14)
Block(0,1,12,17:14)
Block(0,2,-7,17:14)
Block(0,2,8,18:2)
Block(0,2,11,17:14)
Block(0,2,12,17:14)
Block(0,2,15,18:2)
Block(0,3,-7,17:14)
Block(0,3,9,18:2)
Block(0,3,12,17:14)
Block(0,3,14,18:2)
Block(0,3,15,18:2)
Block(0,4,-7,17:14)
Block(0,4,9,18:2)
Block(0,4,10,18:2)
Block(0,4,12,17:14)
Block(0,4,14,18:2)
Block(0,5,-7,17:14)
Block(0,5,10,18:2)
Block(0,5,12,17:14)
Block(0,5,14,18:2)
Block(0,6,-7,17:14)
Block(0,6,10,18:2)
Block(0,6,11,18:2)
Block(0,6,12,17:14)
Block(0,6,13,18:2)
Block(0,6,14,18:2)
Block(0,7,-7,17:14)
Block(0,7,-6,17:14)
Block(0,7,11,18:2)
Block(0,7,12,17:14)
Block(0,7,13,18:2)
Block(0,8,-10,18:2)
Block(0,8,-9,18:2)
Block(0,8,-8,18:2)
Block(0,8,-7,17:14)
Block(0,8,-6,17:14)
Block(0,8,-5,18:2)
Block(0,8,-4,18:2)
Block(0,8,12,17:14)
Block(0,9,-7,17:14)
Block(0,9,-6,18:2)
Block(0,9,-5,18:2)
Block(0,9,-4,18:2)
Block(0,9,-3,18:2)
Block(0,9,11,18:2)
Block(0,9,12,17:14)
Block(0,9,13,18:2)
Block(0,10,-7,17:14)
Block(0,10,-6,18:2)
Block(0,10,-5,18:2)
Block(0,10,10,18:2)
Block(0,10,11,18:2)
Block(0,10,12,17:14)
Block(0,10,13,18:2)
Block(0,11,-10,18:2)
Block(0,11,-9,18:2)
Block(0,11,-8,18:2)
Block(0,11,-7,17:14)
Block(0,11,11,18:2)
Block(0,11,12,17:14)
Block(0,11,13,18:2)
Block(0,12,-7,17:14)
Block(0,12,-6,18:2)
Block(0,12,-5,18:2)
Block(0,12,11,18:2)
Block(0,12,12,18:2)
Block(0,13,-7,17:14)
Block(0,13,12,18:2)
Block(0,14,-7,17:14)
Block(0,14,-6,18:2)
Block(0,14,-5,18:2)
Block(0,14,12,18:2)
Block(0,15,-8,18:2)
Block(0,15,-7,18:2)
Block(0,15,-6,17:14)
Block(0,15,-5,18:2)
Block(0,15,-4,18:2)
Block(0,15,12,18:2)
Block(0,16,-10,18:2)
Block(0,16,-9,18:2)
Block(0,16,-8,18:2)
Block(0,16,-6,18:2)
Block(0,16,-5,18:2)
Block(1,0,-8,17:14)
Block(1,0,12,17:14)
Block(1,1,12,17:14)
Block(1,3,9,18:2)
Block(1,4,10,18:2)
Block(1,5,11,18:2)
Block(1,5,12,18:2)
Block(1,5,13,18:2)
Block(1,5,14,18:2)
Block(1,6,11,18:2)
Block(1,6,12,18:2)
Block(1,6,13,18:2)
Block(1,7,12,18:2)
Block(1,8,-6,18:2)
Block(1,8,-5,18:2)
Block(1,8,-4,18:2)
Block(1,8,12,18:2)
Block(1,9,-8,17:14)
Block(1,9,-7,18:2)
Block(1,9,-6,18:2)
Block(1,9,-5,17:14)
Block(1,9,-4,18:2)
Block(1,9,-3,18:2)
Block(1,9,11,18:2)
Block(1,9,13,18:2)
Block(1,10,-10,18:2)
Block(1,10,-9,18:2)
Block(1,10,-8,17:14)
Block(1,10,-6,18:2)
Block(1,10,-5,18:2)
Block(1,10,-4,18:2)
Block(1,10,12,18:2)
Block(1,10,13,18:2)
Block(1,11,-11,18:2)
Block(1,11,-10,18:2)
Block(1,11,-9,18:2)
Block(1,11,-8,18:2)
Block(1,11,-7,18:2)
Block(1,11,12,18:2)
Block(1,12,-10,18:2)
Block(1,12,-9,18:2)
Block(1,12,-8,18:2)
Block(1,12,11,18:2)
Block(1,12,13,18:2)
Block(1,14,-8,17:14)
Block(1,14,-7,18:2)
Block(1,14,-6,18:2)
Block(1,14,-5,18:2)
Block(1,15,-10,18:2)
Block(1,15,-9,18:2)
Block(1,15,-8,17:14)
Block(1,15,-7,18:2)
Block(1,15,-6,18:2)
Block(1,15,-5,18:2)
Block(1,15,-4,18:2)
Block(1,16,-11,18:2)
Block(1,16,-10,18:2)
Block(1,16,-9,18:2)
Block(1,16,-8,18:2)
Block(1,16,-7,18:2)
Block(1,16,-5,18:2)
Block(1,17,-9,18:2)
Block(1,17,-8,18:2)
Block(2,4,12,18:2)
Block(2,4,13,18:2)
Block(2,5,11,18:2)
Block(2,5,12,18:2)
Block(2,6,12,18:2)
Block(2,8,-6,18:2)
Block(2,8,-5,18:2)
Block(2,8,-4,18:2)
Block(2,8,11,18:2)
Block(2,8,14,18:2)
Block(2,9,-7,18:2)
Block(2,9,-6,18:2)
Block(2,9,-5,18:2)
Block(2,9,-4,18:2)
Block(2,9,-3,18:2)
Block(2,10,-9,18:2)
Block(2,11,-11,18:2)
Block(2,11,-10,18:2)
Block(2,11,-9,17:14)
Block(2,11,-8,18:2)
Block(2,11,-7,18:2)
Block(2,12,-10,18:2)
Block(2,12,-9,18:2)
Block(2,12,-8,18:2)
Block(2,15,-9,18:2)
Block(2,15,-8,18:2)
Block(2,15,-7,18:2)
Block(2,15,-6,18:2)
Block(2,15,-5,18:2)
Block(2,16,-11,18:2)
Block(2,16,-10,18:2)
Block(2,16,-9,17:14)
Block(2,16,-8,18:2)
Block(2,16,-7,18:2)
Block(2,17,-10,18:2)
Block(2,17,-9,18:2)
Block(3,3,12,18:2)
Block(3,4,11,18:2)
Block(3,9,-6,18:2)
Block(3,9,-5,18:2)
Block(3,9,-4,18:2)
Block(3,10,-9,18:2)
Block(3,10,-8,18:2)
Block(3,11,-11,18:2)
Block(3,11,-10,18:2)
Block(3,11,-9,18:2)
Block(3,11,-8,18:2)
Block(3,11,-7,18:2)
Block(3,12,-10,18:2)
Block(3,12,-8,18:2)
Block(3,15,-10,18:2)
Block(3,15,-8,18:2)
Block(3,16,-11,18:2)
Block(3,16,-10,18:2)
Block(3,16,-9,18:2)
Block(3,16,-8,18:2)
Block(3,16,-7,18:2)
Block(3,17,-8,18:2)
Block(4,2,12,18:2)
Block(4,11,-10,18:2)
Block(4,11,-9,18:2)
Block(4,11,-8,18:2)
Block(4,16,-10,18:2)
Block(4,16,-9,18:2)
Block(4,16,-8,18:2)


#######################################################################
# +-----------------------------------------------------------------+ #
# |                             Entities                            | #
# +-----------------------------------------------------------------+ #
#######################################################################

# Entity() spawns an entity instead of a block. The entity is spawned only once when the BO3 is spawned.
# Entities are persistent by default so they don't de-spawn when no player is near, they are only unloaded.
# Usage: Entity(x,y,z,mobName,groupSize,NameTagOrNBTFileName) or Entity(x,y,z,mobName,groupSize)
# Use /tc entities or /otg entities to get a list of entities that can be used as mobName, this includes entities added by other mods.
# NameTagOrNBTFileName can be either a nametag for the mob or an nbt file (such as mymobinfo.nbt or mymobinfo.txt).
# When using a text file you can use the same mob spawning parameters used with the /summon command to equip the
# entity and give it custom attributes etc. You can copy the DATA part of a summon command including surrounding
# curly braces to a .txt file, for instance for: "/summon Skeleton x y z {DATA}"

#######################################################################
# +-----------------------------------------------------------------+ #
# |                            BO3 checks                           | #
# +-----------------------------------------------------------------+ #
#######################################################################

# Require a condition at a certain location in order for the BO3 to be spawned.
# BlockCheck(x,y,z,BlockName[,BlockName[,...]]) - one of the blocks must be at the location
# BlockCheckNot(x,y,z,BlockName[,BlockName[,...]]) - all the blocks must not be at the location
# LightCheck(x,y,z,minLightLevel,maxLightLevel) - light must be between min and max (inclusive)

# You can use "Solid" as a BlockName for matching all solid blocks or "All" to match all blocks that aren't air.

# Examples:
#   BlockCheck(0,-1,0,GRASS,DIRT)  Require grass or dirt just below the object
#   BlockCheck(0,-1,0,Solid)       Require any solid block just below the object
#   BlockCheck(0,-1,0,WOOL)        Require any type of wool just below the object
#   BlockCheck(0,-1,0,WOOL:0)      Require white wool just below the object
#   BlockCheckNot(0,-1,0,WOOL:0)   Require that there is no white wool below the object
#   LightCheck(0,0,0,0,1)          Require almost complete darkness just below the object
BlockCheck(0,-1,0,GRASS,DIRT)
