#######################################################################
# +-----------------------------------------------------------------+ #
# |                            BO3 object                           | #
# +-----------------------------------------------------------------+ #
#######################################################################

# The descriptions in this file are accurate only for TerrainControl and OTG.
# For MCW and OTG+ these descriptions are only accurate if the BO3 is used as a CustomObject.
# MCW and OTG+ completely reimplemented CustomStructure, check the MCW/OTG+ documentation for more information.

# This is the config file of a custom object.
# If you add this object correctly to your BiomeConfigs, it will spawn in the world.

# This is the creator of this BO3 object
Author: Unknown

# A short description of this BO3 object
Description: This BO3 was converted from a schematic using OTGEdit. The author and description information of the schematic could not be found. If you know who the author of the schematic is then please add this information.

# The BO3 version, don't change this! It can be used by external applications to do a version check.
Version: 3

# The settings mode, WriteAll, WriteWithoutComments or WriteDisable. See WorldConfig.
SettingsMode: WriteDisable

#######################################################################
# +-----------------------------------------------------------------+ #
# |                          Main settings                          | #
# +-----------------------------------------------------------------+ #
#######################################################################

# This needs to be set to true to spawn the object in the Tree and Sapling resources.
Tree: true

# The frequency of the BO3 from 1 to 200. Tries this many times to spawn this BO3 when using the CustomObject(...) resource.
# Ignored by Tree(..), Sapling(..) and CustomStructure(..)
Frequency: 2

# The rarity of the BO3 from 0 to 100. Each spawn attempt has rarity% chance to succeed when using the CustomObject(...) resource.
# Ignored by Tree(..), Sapling(..) and CustomStructure(..)
Rarity: 10

# If you set this to true, the BO3 will be placed with a random rotation.
RotateRandomly: true

# The spawn height of the BO3 - randomY, highestBlock or highestSolidBlock.
SpawnHeight: highestSolidBlock

SpawnHeightOffset: -3

# The height limits for the BO3.
MinHeight: 0

MaxHeight: 256

# Objects can have other objects attached to it: branches. Branches can also
# have branches attached to it, which can also have branches, etc. This is the
# maximum branch depth for this objects.
MaxBranchDepth: 10

# When spawned with the UseWorld keyword, this BO3 should NOT spawn in the following biomes.
# If you writer.write the BO3 name directly in the BiomeConfigs, this will be ignored.
ExcludedBiomes: All

# To optimise this BO3 for faster loading times you can use Notepad++ to find/replace comments and abbreviate things.
# Notepad++ find/replace with regex:
# Find: ^[#;].* replace to nothing removes all lines starting with # 
# Find: ^\s*$ replace to nothing removes most empty lines 
# Notepad++ find/replace without regex:
# *Warning: This will only work for OTG 1.10.2 v21 / OTG 1.11.2 v6 or higher. B( is not recognised by lower versions.
# Find: Block( replace to B(

#######################################################################
# +-----------------------------------------------------------------+ #
# |                      Source block settings                      | #
# +-----------------------------------------------------------------+ #
#######################################################################

# The block(s) the BO3 should spawn in.
SourceBlocks: AIR

# The maximum percentage of the BO3 that can be outside the SourceBlock.
# The BO3 won't be placed on a location with more blocks outside the SourceBlock than this percentage.
MaxPercentageOutsideSourceBlock: 100

# What to do when a block is about to be placed outside the SourceBlock? (dontPlace, placeAnyway)
OutsideSourceBlock: placeAnyway

#######################################################################
# +-----------------------------------------------------------------+ #
# |                              Blocks                             | #
# +-----------------------------------------------------------------+ #
#######################################################################

# All the blocks used in the BO3 are listed here. Possible blocks:
# Block(x,y,z,id[.data][,nbtfile.nbt) or B(x,y,z,id[.data][,nbtfile.nbt)
# RandomBlock(x,y,z,id[:data][,nbtfile.nbt],chance[,id[:data][,nbtfile.nbt],chance[,...]])
# So RandomBlock(0,0,0,CHEST,chest.nbt,50,CHEST,anotherchest.nbt,100) will spawn a chest at
# the BO3 origin, and give it a 50% chance to have the contents of chest.nbt, or, if that
# fails, a 100% percent chance to have the contents of anotherchest.nbt.

Block(-15,14,-2,179:2)
Block(-15,14,1,179:2)
Block(-14,15,-2,159:1)
Block(-14,16,2,159:1)
Block(-14,18,0,159:1)
Block(-13,5,-4,159:1)
Block(-13,6,-4,126:4)
Block(-13,10,-1,182)
Block(-13,14,-3,159:1)
Block(-13,14,0,159:1)
Block(-13,15,-5,179:2)
Block(-13,15,-2,159:1)
Block(-13,15,-1,179:2)
Block(-13,16,-3,179:2)
Block(-13,16,-1,17:13)
Block(-13,17,-4,179:2)
Block(-13,17,0,179:2)
Block(-13,17,5,179:2)
Block(-13,18,-1,179:2)
Block(-13,18,4,159:1)
Block(-13,18,5,159:1)
Block(-13,19,0,159:1)
Block(-12,3,-4,17:13)
Block(-12,4,-4,17:13)
Block(-12,5,-5,182)
Block(-12,5,-4,17:13)
Block(-12,6,-5,126:4)
Block(-12,6,-4,17:13)
Block(-12,7,-5,159:1)
Block(-12,7,-4,17:13)
Block(-12,7,-3,17:13)
Block(-12,8,-4,179:2)
Block(-12,8,-3,17:13)
Block(-12,8,-2,179:2)
Block(-12,9,-3,179:2)
Block(-12,9,-2,179:2)
Block(-12,10,-2,126:4)
Block(-12,13,-2,179:2)
Block(-12,13,-1,179:2)
Block(-12,13,0,159:1)
Block(-12,15,-5,159:1)
Block(-12,15,-4,179:2)
Block(-12,15,-3,179:2)
Block(-12,15,-2,17:13)
Block(-12,15,1,179:2)
Block(-12,15,5,179:2)
Block(-12,16,-5,159:1)
Block(-12,16,-3,179:2)
Block(-12,16,-2,17:13)
Block(-12,16,-1,17:13)
Block(-12,16,1,179:2)
Block(-12,16,5,179:2)
Block(-12,17,-1,159:1)
Block(-12,17,1,159:1)
Block(-12,17,5,159:1)
Block(-12,17,6,159:1)
Block(-12,18,-3,159:1)
Block(-12,18,2,159:1)
Block(-12,18,3,159:1)
Block(-12,19,1,159:1)
Block(-12,19,2,179:2)
Block(-12,19,5,159:1)
Block(-12,20,2,182)
Block(-12,20,3,126:4)
Block(-12,21,2,159:1)
Block(-11,5,-3,126:4)
Block(-11,7,-4,159:1)
Block(-11,7,-3,126:4)
Block(-11,7,-2,159:1)
Block(-11,8,-4,159:1)
Block(-11,8,-3,17:13)
Block(-11,8,-2,17:13)
Block(-11,9,-3,17:13)
Block(-11,9,-2,17:13)
Block(-11,9,-1,17:13)
Block(-11,10,-4,126:4)
Block(-11,10,-2,179:2)
Block(-11,10,-1,17:13)
Block(-11,10,0,179:2)
Block(-11,11,-2,126:4)
Block(-11,11,-1,159:1)
Block(-11,13,-4,159:1)
Block(-11,13,-2,179:2)
Block(-11,13,-1,179:2)
Block(-11,14,-4,159:1)
Block(-11,14,-3,179:2)
Block(-11,15,-6,179:2)
Block(-11,15,-4,159:1)
Block(-11,15,-3,17:13)
Block(-11,15,-2,17:13)
Block(-11,15,3,179:2)
Block(-11,16,-3,179:2)
Block(-11,16,1,179:2)
Block(-11,16,2,159:1)
Block(-11,16,8,179:2)
Block(-11,17,-4,159:1)
Block(-11,17,-3,179:2)
Block(-11,17,-1,159:1)
Block(-11,17,0,159:1)
Block(-11,17,1,159:1)
Block(-11,17,2,179:2)
Block(-11,17,5,17:13)
Block(-11,17,7,179:2)
Block(-11,18,-1,179:2)
Block(-11,18,2,159:1)
Block(-11,18,3,179:2)
Block(-11,18,8,182)
Block(-11,19,2,182)
Block(-11,19,3,179:2)
Block(-11,19,9,182)
Block(-11,20,1,159:1)
Block(-11,20,2,126:4)
Block(-11,20,3,126:4)
Block(-11,20,4,182)
Block(-11,20,9,159:1)
Block(-11,21,3,179:2)
Block(-11,21,10,159:1)
Block(-10,8,-3,159:1)
Block(-10,8,11,159:1)
Block(-10,9,-3,182)
Block(-10,9,-2,159:1)
Block(-10,9,-1,17:13)
Block(-10,9,11,159:1)
Block(-10,10,-1,17:13)
Block(-10,10,0,17:13)
Block(-10,11,-2,182)
Block(-10,11,-1,126:4)
Block(-10,11,0,17:13)
Block(-10,11,1,17:13)
Block(-10,12,-6,159:1)
Block(-10,12,-5,159:1)
Block(-10,12,-2,126:4)
Block(-10,12,-1,179:2)
Block(-10,12,0,17:13)
Block(-10,13,-5,179:2)
Block(-10,13,-4,179:2)
Block(-10,13,-3,17:13)
Block(-10,13,-2,182)
Block(-10,13,-1,179:2)
Block(-10,14,-6,179:2)
Block(-10,14,-4,182)
Block(-10,14,-3,17:13)
Block(-10,14,-1,179:2)
Block(-10,14,0,159:1)
Block(-10,14,1,179:2)
Block(-10,14,4,179:2)
Block(-10,15,-3,17:13)
Block(-10,15,-1,159:1)
Block(-10,15,4,159:1)
Block(-10,15,6,179:2)
Block(-10,15,7,159:1)
Block(-10,16,-6,179:2)
Block(-10,16,-5,179:2)
Block(-10,16,-3,126:4)
Block(-10,16,-2,159:1)
Block(-10,16,-1,159:1)
Block(-10,16,0,159:1)
Block(-10,16,4,179:2)
Block(-10,16,5,179:2)
Block(-10,17,-6,159:1)
Block(-10,17,-1,159:1)
Block(-10,17,2,179:2)
Block(-10,17,5,17:13)
Block(-10,18,-6,159:1)
Block(-10,18,-1,159:1)
Block(-10,18,2,159:1)
Block(-10,18,3,159:1)
Block(-10,18,4,179:2)
Block(-10,18,5,179:2)
Block(-10,18,7,179:2)
Block(-10,18,8,17:13)
Block(-10,18,9,182)
Block(-10,18,10,159:1)
Block(-10,19,1,159:1)
Block(-10,19,2,179:2)
Block(-10,19,3,159:1)
Block(-10,19,4,179:2)
Block(-10,19,8,17:13)
Block(-10,19,9,17:13)
Block(-10,20,2,179:2)
Block(-10,20,3,179:2)
Block(-10,20,4,179:2)
Block(-10,20,5,126:4)
Block(-10,20,9,17:13)
Block(-10,20,10,17:13)
Block(-10,20,11,159:1)
Block(-10,21,8,179:2)
Block(-10,22,8,179:2)
Block(-10,22,12,159:1)
Block(-9,7,11,17:13)
Block(-9,7,12,159:1)
Block(-9,8,11,17:13)
Block(-9,9,10,17:13)
Block(-9,9,11,17:13)
Block(-9,10,-2,179:2)
Block(-9,10,0,182)
Block(-9,10,10,17:13)
Block(-9,10,11,159:1)
Block(-9,10,12,182)
Block(-9,11,-6,179:2)
Block(-9,11,-5,159:1)
Block(-9,11,-4,179:2)
Block(-9,11,0,17:13)
Block(-9,11,1,17:13)
Block(-9,11,2,17:13)
Block(-9,11,11,159:1)
Block(-9,12,-5,159:1)
Block(-9,12,-4,159:1)
Block(-9,12,-2,17:13)
Block(-9,12,-1,17:13)
Block(-9,12,0,17:13)
Block(-9,12,1,179:2)
Block(-9,12,9,159:1)
Block(-9,12,10,179:2)
Block(-9,13,-6,179:2)
Block(-9,13,-4,17:13)
Block(-9,13,-3,17:13)
Block(-9,13,-2,17:13)
Block(-9,13,-1,17:13)
Block(-9,14,-6,159:1)
Block(-9,14,-4,179:2)
Block(-9,14,-3,159:1)
Block(-9,14,6,159:1)
Block(-9,14,7,179:2)
Block(-9,14,9,182)
Block(-9,15,-5,159:1)
Block(-9,15,-4,179:2)
Block(-9,15,-3,182)
Block(-9,15,-2,179:2)
Block(-9,15,2,159:1)
Block(-9,15,5,179:2)
Block(-9,15,6,126:4)
Block(-9,15,9,126:4)
Block(-9,15,10,179:2)
Block(-9,16,-4,159:1)
Block(-9,16,-3,159:1)
Block(-9,16,-2,179:2)
Block(-9,16,-1,159:1)
Block(-9,16,0,179:2)
Block(-9,16,1,179:2)
Block(-9,16,2,159:1)
Block(-9,16,3,179:2)
Block(-9,16,6,159:1)
Block(-9,17,-7,179:2)
Block(-9,17,-3,179:2)
Block(-9,17,0,159:1)
Block(-9,17,4,159:1)
Block(-9,17,5,17:13)
Block(-9,17,6,17:13)
Block(-9,17,7,17:13)
Block(-9,18,-6,159:1)
Block(-9,18,-4,159:1)
Block(-9,18,-1,159:1)
Block(-9,18,1,179:2)
Block(-9,18,7,17:13)
Block(-9,18,8,17:13)
Block(-9,19,2,179:2)
Block(-9,19,3,179:2)
Block(-9,19,8,179:2)
Block(-9,19,9,126:4)
Block(-9,19,11,179:2)
Block(-9,19,12,179:2)
Block(-9,20,4,179:2)
Block(-9,20,5,159:1)
Block(-9,20,7,179:2)
Block(-9,20,9,159:1)
Block(-9,20,10,17:13)
Block(-9,21,5,179:2)
Block(-9,21,6,179:2)
Block(-9,21,10,17:13)
Block(-9,21,11,17:13)
Block(-9,22,6,179:2)
Block(-9,22,7,159:1)
Block(-9,22,9,159:1)
Block(-9,23,4,159:1)
Block(-9,23,6,182)
Block(-8,8,11,126:4)
Block(-8,8,12,179:2)
Block(-8,9,11,126:4)
Block(-8,10,10,17:13)
Block(-8,10,11,179:2)
Block(-8,11,-5,159:1)
Block(-8,11,2,17:13)
Block(-8,11,10,17:13)
Block(-8,12,-1,159:1)
Block(-8,12,2,17:13)
Block(-8,12,9,179:2)
Block(-8,12,10,17:13)
Block(-8,12,11,159:1)
Block(-8,13,-5,179:2)
Block(-8,13,-4,159:1)
Block(-8,13,-3,17:13)
Block(-8,13,8,182)
Block(-8,13,9,126:4)
Block(-8,13,10,126:4)
Block(-8,14,-7,159:1)
Block(-8,14,-4,179:2)
Block(-8,14,-3,17:13)
Block(-8,14,8,159:1)
Block(-8,14,9,179:2)
Block(-8,14,10,159:1)
Block(-8,15,-8,159:1)
Block(-8,15,-7,179:2)
Block(-8,15,-6,159:1)
Block(-8,15,-4,159:1)
Block(-8,15,-2,179:2)
Block(-8,15,1,159:1)
Block(-8,15,6,159:1)
Block(-8,15,8,126:4)
Block(-8,15,9,182)
Block(-8,15,10,126:4)
Block(-8,16,-7,179:2)
Block(-8,16,-6,179:2)
Block(-8,16,-5,179:2)
Block(-8,16,-4,179:2)
Block(-8,16,-3,159:1)
Block(-8,16,-2,179:2)
Block(-8,16,-1,179:2)
Block(-8,16,3,179:2)
Block(-8,16,6,17:13)
Block(-8,16,7,17:13)
Block(-8,16,9,179:2)
Block(-8,16,10,179:2)
Block(-8,16,11,126:4)
Block(-8,17,-7,179:2)
Block(-8,17,-6,159:1)
Block(-8,17,-4,179:2)
Block(-8,17,0,159:1)
Block(-8,17,1,159:1)
Block(-8,17,6,17:13)
Block(-8,17,7,17:13)
Block(-8,18,-9,179:2)
Block(-8,18,-6,179:2)
Block(-8,18,-5,182)
Block(-8,18,-2,179:2)
Block(-8,18,5,179:2)
Block(-8,19,5,179:2)
Block(-8,19,6,179:2)
Block(-8,19,9,159:1)
Block(-8,20,9,179:2)
Block(-8,20,10,179:2)
Block(-8,21,10,17:13)
Block(-8,21,11,17:13)
Block(-8,22,3,179:2)
Block(-8,22,6,159:1)
Block(-8,22,8,179:2)
Block(-8,22,11,179:2)
Block(-8,22,14,159:1)
Block(-8,23,4,179:2)
Block(-8,23,6,179:2)
Block(-8,23,7,159:1)
Block(-7,11,10,126:4)
Block(-7,12,2,17:13)
Block(-7,12,3,17:13)
Block(-7,12,9,17:13)
Block(-7,12,10,17:13)
Block(-7,13,8,182)
Block(-7,13,9,17:13)
Block(-7,13,10,182)
Block(-7,14,-6,159:1)
Block(-7,14,-4,17:13)
Block(-7,14,-3,17:13)
Block(-7,14,9,17:13)
Block(-7,15,-5,159:1)
Block(-7,15,-4,17:13)
Block(-7,15,-2,179:2)
Block(-7,15,5,179:2)
Block(-7,15,7,17:13)
Block(-7,15,8,17:13)
Block(-7,15,9,179:2)
Block(-7,16,-9,126:4)
Block(-7,16,-6,17:13)
Block(-7,16,-4,179:2)
Block(-7,16,-2,179:2)
Block(-7,16,1,159:1)
Block(-7,16,5,159:1)
Block(-7,16,7,17:13)
Block(-7,16,8,17:13)
Block(-7,17,-9,179:2)
Block(-7,17,-8,159:1)
Block(-7,17,-6,126:4)
Block(-7,17,-2,159:1)
Block(-7,17,0,179:2)
Block(-7,17,1,159:1)
Block(-7,17,2,159:1)
Block(-7,17,8,182)
Block(-7,17,9,126:4)
Block(-7,18,-5,159:1)
Block(-7,18,-2,159:1)
Block(-7,18,1,159:1)
Block(-7,18,2,159:1)
Block(-7,18,5,179:2)
Block(-7,19,-6,159:1)
Block(-7,19,-5,126:4)
Block(-7,19,1,159:1)
Block(-7,19,6,159:1)
Block(-7,19,11,159:1)
Block(-7,20,-7,159:1)
Block(-7,20,8,159:1)
Block(-7,20,9,159:1)
Block(-7,21,3,159:1)
Block(-7,21,5,179:2)
Block(-7,21,6,179:2)
Block(-7,21,8,159:1)
Block(-7,21,10,179:2)
Block(-7,21,11,17:13)
Block(-7,22,4,179:2)
Block(-7,22,7,182)
Block(-7,22,11,179:2)
Block(-7,23,6,179:2)
Block(-7,23,11,159:1)
Block(-7,24,9,179:2)
Block(-7,24,12,179:2)
Block(-6,11,-7,182)
Block(-6,11,3,17:13)
Block(-6,12,-8,159:1)
Block(-6,12,-4,159:1)
Block(-6,12,3,17:13)
Block(-6,12,9,179:2)
Block(-6,13,-7,159:1)
Block(-6,13,-6,179:2)
Block(-6,13,-5,17:13)
Block(-6,13,7,17:13)
Block(-6,13,8,17:13)
Block(-6,14,-6,126:4)
Block(-6,14,-5,17:13)
Block(-6,14,-4,17:13)
Block(-6,14,6,17:13)
Block(-6,14,7,17:13)
Block(-6,14,8,17:13)
Block(-6,14,9,17:13)
Block(-6,14,10,179:2)
Block(-6,15,-9,159:1)
Block(-6,15,-6,179:2)
Block(-6,15,-5,17:13)
Block(-6,15,-4,17:13)
Block(-6,15,0,159:1)
Block(-6,15,1,179:2)
Block(-6,15,7,17:13)
Block(-6,15,8,17:13)
Block(-6,16,-8,159:1)
Block(-6,16,-7,17:13)
Block(-6,16,-6,17:13)
Block(-6,16,-5,17:13)
Block(-6,16,-4,179:2)
Block(-6,16,0,179:2)
Block(-6,16,1,159:1)
Block(-6,16,2,159:1)
Block(-6,16,8,17:13)
Block(-6,17,-9,179:2)
Block(-6,17,-8,179:2)
Block(-6,17,-7,17:13)
Block(-6,17,-6,159:1)
Block(-6,17,0,159:1)
Block(-6,17,1,159:1)
Block(-6,17,2,179:2)
Block(-6,17,7,126:4)
Block(-6,17,9,182)
Block(-6,18,-10,159:1)
Block(-6,18,-7,179:2)
Block(-6,18,-2,179:2)
Block(-6,18,2,159:1)
Block(-6,18,3,179:2)
Block(-6,18,9,179:2)
Block(-6,18,10,182)
Block(-6,18,11,159:1)
Block(-6,19,-7,179:2)
Block(-6,19,-3,159:1)
Block(-6,19,-2,159:1)
Block(-6,19,-1,126:4)
Block(-6,19,2,159:1)
Block(-6,19,4,159:1)
Block(-6,19,8,159:1)
Block(-6,19,9,179:2)
Block(-6,19,10,159:1)
Block(-6,19,11,159:1)
Block(-6,20,-7,159:1)
Block(-6,20,-2,179:2)
Block(-6,20,1,179:2)
Block(-6,20,3,179:2)
Block(-6,20,7,159:1)
Block(-6,20,8,179:2)
Block(-6,20,9,179:2)
Block(-6,20,10,179:2)
Block(-6,21,-3,159:1)
Block(-6,21,6,179:2)
Block(-6,22,9,179:2)
Block(-6,23,4,179:2)
Block(-6,23,9,179:2)
Block(-6,23,10,179:2)
Block(-6,23,11,179:2)
Block(-6,23,12,159:1)
Block(-6,23,13,159:1)
Block(-6,24,6,179:2)
Block(-6,24,11,179:2)
Block(-5,0,-3,17:13)
Block(-5,1,-2,17:13)
Block(-5,10,-7,126:4)
Block(-5,10,-6,159:1)
Block(-5,10,-5,159:1)
Block(-5,11,-7,159:1)
Block(-5,11,-6,182)
Block(-5,11,3,17:13)
Block(-5,11,4,17:13)
Block(-5,12,-7,17:13)
Block(-5,12,-6,17:13)
Block(-5,12,5,17:13)
Block(-5,12,6,17:13)
Block(-5,13,-7,182)
Block(-5,13,-6,17:13)
Block(-5,13,-5,17:13)
Block(-5,13,5,17:13)
Block(-5,13,6,17:13)
Block(-5,14,-7,159:1)
Block(-5,14,-6,159:1)
Block(-5,14,-1,179:2)
Block(-5,14,6,17:13)
Block(-5,14,7,17:13)
Block(-5,15,-6,159:1)
Block(-5,15,0,159:1)
Block(-5,15,7,17:13)
Block(-5,15,9,159:1)
Block(-5,16,-3,179:2)
Block(-5,16,3,179:2)
Block(-5,16,6,159:1)
Block(-5,16,8,17:13)
Block(-5,17,-4,179:2)
Block(-5,17,-1,159:1)
Block(-5,17,1,159:1)
Block(-5,17,2,182)
Block(-5,17,8,17:13)
Block(-5,17,9,159:1)
Block(-5,17,12,179:2)
Block(-5,18,-9,179:2)
Block(-5,18,-7,179:2)
Block(-5,18,-5,159:1)
Block(-5,18,-4,159:1)
Block(-5,18,-3,179:2)
Block(-5,18,0,179:2)
Block(-5,18,2,159:1)
Block(-5,18,3,179:2)
Block(-5,18,5,159:1)
Block(-5,18,6,179:2)
Block(-5,18,7,179:2)
Block(-5,18,11,179:2)
Block(-5,19,-5,179:2)
Block(-5,19,-4,159:1)
Block(-5,19,-3,179:2)
Block(-5,19,-2,159:1)
Block(-5,19,-1,179:2)
Block(-5,19,0,179:2)
Block(-5,19,8,179:2)
Block(-5,19,9,179:2)
Block(-5,19,10,179:2)
Block(-5,19,11,159:1)
Block(-5,20,-8,179:2)
Block(-5,20,-2,179:2)
Block(-5,20,-1,159:1)
Block(-5,20,0,159:1)
Block(-5,20,9,179:2)
Block(-5,20,11,159:1)
Block(-5,21,8,159:1)
Block(-5,21,9,179:2)
Block(-5,21,11,159:1)
Block(-5,21,13,159:1)
Block(-5,22,-6,159:1)
Block(-5,22,-5,182)
Block(-5,22,-3,159:1)
Block(-5,22,3,159:1)
Block(-5,22,4,179:2)
Block(-5,22,11,159:1)
Block(-5,23,-6,179:2)
Block(-5,23,11,159:1)
Block(-5,23,12,159:1)
Block(-5,24,-6,179:2)
Block(-4,0,-3,17:13)
Block(-4,1,-3,17:13)
Block(-4,1,-2,17:13)
Block(-4,2,-2,17:13)
Block(-4,8,-8,17:13)
Block(-4,9,-8,17:13)
Block(-4,10,-9,179:2)
Block(-4,10,-8,17:13)
Block(-4,10,-7,17:13)
Block(-4,10,-6,182)
Block(-4,11,-8,159:1)
Block(-4,11,-7,17:13)
Block(-4,11,-6,179:2)
Block(-4,11,3,17:13)
Block(-4,11,4,17:13)
Block(-4,12,-8,179:2)
Block(-4,12,-7,17:13)
Block(-4,12,-6,159:1)
Block(-4,12,4,17:13)
Block(-4,12,5,17:13)
Block(-4,13,-8,126:4)
Block(-4,13,4,17:13)
Block(-4,14,-5,126:4)
Block(-4,15,-7,179:2)
Block(-4,15,-6,179:2)
Block(-4,15,-1,179:2)
Block(-4,16,-7,159:1)
Block(-4,16,-4,179:2)
Block(-4,16,3,179:2)
Block(-4,16,5,179:2)
Block(-4,16,12,159:1)
Block(-4,17,-9,126:4)
Block(-4,17,-8,159:1)
Block(-4,17,-6,179:2)
Block(-4,17,-1,159:1)
Block(-4,17,0,179:2)
Block(-4,17,5,159:1)
Block(-4,17,8,17:13)
Block(-4,18,-8,159:1)
Block(-4,18,-7,159:1)
Block(-4,18,-6,179:2)
Block(-4,18,-5,179:2)
Block(-4,18,-4,159:1)
Block(-4,18,-3,179:2)
Block(-4,18,-2,179:2)
Block(-4,18,-1,159:1)
Block(-4,18,0,179:2)
Block(-4,18,5,179:2)
Block(-4,18,7,179:2)
Block(-4,18,11,159:1)
Block(-4,19,-5,179:2)
Block(-4,19,-4,159:1)
Block(-4,19,-3,159:1)
Block(-4,19,-2,179:2)
Block(-4,19,0,182)
Block(-4,19,2,159:1)
Block(-4,19,11,179:2)
Block(-4,20,-5,179:2)
Block(-4,20,-4,179:2)
Block(-4,20,-3,159:1)
Block(-4,20,-2,179:2)
Block(-4,21,-7,159:1)
Block(-4,21,-5,179:2)
Block(-4,21,-2,179:2)
Block(-4,21,4,179:2)
Block(-4,21,7,159:1)
Block(-4,21,8,179:2)
Block(-4,21,13,179:2)
Block(-4,22,-8,179:2)
Block(-4,22,-6,126:4)
Block(-4,22,-5,159:1)
Block(-4,22,9,159:1)
Block(-4,22,10,179:2)
Block(-4,22,11,179:2)
Block(-4,23,-6,159:1)
Block(-4,24,-7,126:4)
Block(-3,0,-2,188)
Block(-3,0,-1,17:13)
Block(-3,0,0,17:13)
Block(-3,1,-2,17:13)
Block(-3,1,-1,17:13)
Block(-3,2,-3,17:13)
Block(-3,2,-2,17:13)
Block(-3,10,-8,159:1)
Block(-3,10,3,17:13)
Block(-3,11,-7,159:1)
Block(-3,11,2,182)
Block(-3,11,3,17:13)
Block(-3,11,4,17:13)
Block(-3,12,-7,159:1)
Block(-3,12,3,17:13)
Block(-3,12,4,17:13)
Block(-3,15,-7,179:2)
Block(-3,15,-1,159:1)
Block(-3,15,0,159:1)
Block(-3,16,-8,179:2)
Block(-3,16,-3,159:1)
Block(-3,16,2,179:2)
Block(-3,16,8,159:1)
Block(-3,16,11,159:1)
Block(-3,17,-10,159:1)
Block(-3,17,-8,159:1)
Block(-3,17,-4,179:2)
Block(-3,17,-2,159:1)
Block(-3,17,1,159:1)
Block(-3,17,7,179:2)
Block(-3,17,8,17:13)
Block(-3,17,9,159:1)
Block(-3,17,11,179:2)
Block(-3,18,-10,159:1)
Block(-3,18,-8,159:1)
Block(-3,18,-7,159:1)
Block(-3,18,-5,179:2)
Block(-3,18,-3,182)
Block(-3,18,-2,126:4)
Block(-3,18,0,159:1)
Block(-3,18,7,17:13)
Block(-3,18,8,17:13)
Block(-3,18,9,159:1)
Block(-3,18,11,159:1)
Block(-3,18,14,159:1)
Block(-3,19,-10,179:2)
Block(-3,19,-9,179:2)
Block(-3,19,-7,159:1)
Block(-3,19,-4,179:2)
Block(-3,19,-3,182)
Block(-3,19,-2,159:1)
Block(-3,19,-1,179:2)
Block(-3,19,1,179:2)
Block(-3,19,3,179:2)
Block(-3,19,5,159:1)
Block(-3,19,7,179:2)
Block(-3,19,8,179:2)
Block(-3,19,11,159:1)
Block(-3,20,-8,179:2)
Block(-3,20,-6,179:2)
Block(-3,20,2,179:2)
Block(-3,20,3,179:2)
Block(-3,20,5,179:2)
Block(-3,20,6,179:2)
Block(-3,20,7,159:1)
Block(-3,20,9,159:1)
Block(-3,21,-9,159:1)
Block(-3,21,-8,159:1)
Block(-3,21,-4,179:2)
Block(-3,21,1,159:1)
Block(-3,21,2,159:1)
Block(-3,21,3,159:1)
Block(-3,21,5,179:2)
Block(-3,21,11,179:2)
Block(-3,21,13,159:1)
Block(-3,22,-6,179:2)
Block(-3,22,-5,179:2)
Block(-3,22,2,159:1)
Block(-3,22,11,159:1)
Block(-3,23,-5,159:1)
Block(-2,1,-2,17:13)
Block(-2,2,-2,17:13)
Block(-2,2,-1,17:13)
Block(-2,3,-1,17:13)
Block(-2,4,-1,17:13)
Block(-2,9,2,17:13)
Block(-2,9,3,17:13)
Block(-2,10,2,17:13)
Block(-2,10,3,17:13)
Block(-2,10,4,17:13)
Block(-2,11,2,126:4)
Block(-2,11,3,17:13)
Block(-2,11,4,17:13)
Block(-2,15,10,159:1)
Block(-2,16,9,159:1)
Block(-2,17,-5,179:2)
Block(-2,17,-2,159:1)
Block(-2,17,10,179:2)
Block(-2,18,-8,159:1)
Block(-2,18,6,17:13)
Block(-2,18,7,17:13)
Block(-2,18,8,159:1)
Block(-2,18,9,179:2)
Block(-2,19,-6,179:2)
Block(-2,19,-1,179:2)
Block(-2,19,1,159:1)
Block(-2,19,6,179:2)
Block(-2,19,8,159:1)
Block(-2,19,10,159:1)
Block(-2,19,11,159:1)
Block(-2,19,12,159:1)
Block(-2,19,14,179:2)
Block(-2,20,-8,159:1)
Block(-2,20,3,179:2)
Block(-2,20,4,179:2)
Block(-2,20,7,179:2)
Block(-2,20,8,182)
Block(-2,20,9,126:4)
Block(-2,20,10,182)
Block(-2,21,-8,179:2)
Block(-2,21,-7,179:2)
Block(-2,21,-6,17:13)
Block(-2,21,-5,17:13)
Block(-2,21,-4,179:2)
Block(-2,21,-3,179:2)
Block(-2,21,4,159:1)
Block(-2,21,8,179:2)
Block(-2,21,9,159:1)
Block(-2,21,11,179:2)
Block(-2,21,12,179:2)
Block(-2,22,-8,159:1)
Block(-2,22,-1,179:2)
Block(-2,22,4,179:2)
Block(-2,22,8,126:4)
Block(-2,22,12,179:2)
Block(-2,22,13,182)
Block(-2,23,-7,159:1)
Block(-2,23,-6,126:4)
Block(-2,23,-4,182)
Block(-2,23,-1,179:2)
Block(-2,23,0,179:2)
Block(-2,24,-7,159:1)
Block(-1,2,-2,17:13)
Block(-1,2,-1,17:13)
Block(-1,2,0,17:13)
Block(-1,3,-1,17:13)
Block(-1,3,0,17:13)
Block(-1,4,-1,17:13)
Block(-1,4,0,17:13)
Block(-1,5,-1,17:13)
Block(-1,6,0,17:13)
Block(-1,6,1,17:13)
Block(-1,8,1,17:13)
Block(-1,8,2,17:13)
Block(-1,9,2,17:13)
Block(-1,10,1,17:13)
Block(-1,10,2,17:13)
Block(-1,10,3,17:13)
Block(-1,11,2,17:13)
Block(-1,11,3,179:2)
Block(-1,16,8,179:2)
Block(-1,16,9,159:1)
Block(-1,16,10,159:1)
Block(-1,18,-8,159:1)
Block(-1,18,-6,179:2)
Block(-1,18,-4,179:2)
Block(-1,18,3,159:1)
Block(-1,18,4,179:2)
Block(-1,18,6,17:13)
Block(-1,18,9,179:2)
Block(-1,18,10,182)
Block(-1,18,11,179:2)
Block(-1,18,12,159:1)
Block(-1,19,-8,179:2)
Block(-1,19,-7,159:1)
Block(-1,19,-5,159:1)
Block(-1,19,-4,159:1)
Block(-1,19,-3,179:2)
Block(-1,19,-2,159:1)
Block(-1,19,1,159:1)
Block(-1,19,3,179:2)
Block(-1,19,6,159:1)
Block(-1,19,7,159:1)
Block(-1,19,10,159:1)
Block(-1,20,-8,159:1)
Block(-1,20,-6,179:2)
Block(-1,20,-5,159:1)
Block(-1,20,-4,17:13)
Block(-1,20,-3,159:1)
Block(-1,20,0,179:2)
Block(-1,20,3,179:2)
Block(-1,20,4,179:2)
Block(-1,20,8,179:2)
Block(-1,20,11,126:4)
Block(-1,21,-9,179:2)
Block(-1,21,-8,159:1)
Block(-1,21,-6,159:1)
Block(-1,21,-5,17:13)
Block(-1,21,-4,17:13)
Block(-1,21,3,159:1)
Block(-1,21,6,126:4)
Block(-1,21,8,179:2)
Block(-1,21,9,179:2)
Block(-1,21,10,179:2)
Block(-1,22,-7,159:1)
Block(-1,22,-6,179:2)
Block(-1,22,-3,182)
Block(-1,22,-1,179:2)
Block(-1,22,0,182)
Block(-1,22,3,182)
Block(-1,22,4,182)
Block(-1,22,12,179:2)
Block(-1,23,-10,159:1)
Block(-1,23,-8,159:1)
Block(-1,23,-6,159:1)
Block(-1,23,-5,159:1)
Block(-1,23,-4,159:1)
Block(-1,23,-1,179:2)
Block(-1,23,0,182)
Block(-1,23,1,159:1)
Block(-1,24,-5,182)
Block(-1,24,1,159:1)
Block(0,0,0,188)
Block(0,0,1,17:13)
Block(0,0,2,17:13)
Block(0,0,3,17:13)
Block(0,1,0,17:13)
Block(0,1,1,17:13)
Block(0,2,-4,17:13)
Block(0,2,-3,17:13)
Block(0,2,-2,17:13)
Block(0,2,-1,17:13)
Block(0,2,0,17:13)
Block(0,3,-2,17:13)
Block(0,3,-1,17:13)
Block(0,4,-1,17:13)
Block(0,4,0,17:13)
Block(0,5,-1,17:13)
Block(0,5,0,17:13)
Block(0,6,-1,17:13)
Block(0,6,0,17:13)
Block(0,6,1,17:13)
Block(0,6,2,17:13)
Block(0,7,1,17:13)
Block(0,7,2,17:13)
Block(0,8,0,17:13)
Block(0,8,1,17:13)
Block(0,8,2,17:13)
Block(0,9,0,17:13)
Block(0,14,10,159:1)
Block(0,15,12,179:2)
Block(0,16,6,159:1)
Block(0,16,7,179:2)
Block(0,16,10,17:13)
Block(0,17,-7,182)
Block(0,17,6,159:1)
Block(0,17,7,159:1)
Block(0,18,-10,159:1)
Block(0,18,-8,159:1)
Block(0,18,-7,179:2)
Block(0,18,2,159:1)
Block(0,18,6,159:1)
Block(0,18,8,179:2)
Block(0,18,11,159:1)
Block(0,19,-10,179:2)
Block(0,19,-9,126:4)
Block(0,19,-8,182)
Block(0,19,-4,17:13)
Block(0,19,-3,159:1)
Block(0,19,-1,159:1)
Block(0,19,0,179:2)
Block(0,19,1,159:1)
Block(0,19,3,159:1)
Block(0,19,7,179:2)
Block(0,19,8,179:2)
Block(0,19,11,179:2)
Block(0,20,-9,159:1)
Block(0,20,-6,179:2)
Block(0,20,-5,159:1)
Block(0,20,-4,17:13)
Block(0,20,-3,17:13)
Block(0,20,-2,17:13)
Block(0,20,-1,159:1)
Block(0,20,6,179:2)
Block(0,20,8,179:2)
Block(0,20,10,182)
Block(0,20,12,179:2)
Block(0,21,-8,179:2)
Block(0,21,-6,159:1)
Block(0,21,-2,17:13)
Block(0,21,0,159:1)
Block(0,21,1,179:2)
Block(0,21,3,179:2)
Block(0,21,4,159:1)
Block(0,22,-9,159:1)
Block(0,22,-6,159:1)
Block(0,22,-5,179:2)
Block(0,22,-4,179:2)
Block(0,22,-3,182)
Block(0,22,-2,159:1)
Block(0,22,-1,179:2)
Block(0,22,0,182)
Block(0,22,2,159:1)
Block(0,22,3,182)
Block(0,23,-8,179:2)
Block(0,23,-7,159:1)
Block(0,23,-6,126:4)
Block(0,23,-4,179:2)
Block(0,23,-2,159:1)
Block(0,23,0,159:1)
Block(0,23,2,179:2)
Block(0,23,3,159:1)
Block(0,24,1,179:2)
Block(0,24,2,179:2)
Block(1,1,0,17:13)
Block(1,1,1,17:13)
Block(1,2,-4,17:13)
Block(1,2,-3,17:13)
Block(1,2,-2,17:13)
Block(1,2,-1,17:13)
Block(1,2,0,17:13)
Block(1,5,0,17:13)
Block(1,5,1,17:13)
Block(1,6,1,17:13)
Block(1,6,2,17:13)
Block(1,7,-1,17:13)
Block(1,7,0,17:13)
Block(1,7,1,17:13)
Block(1,7,2,17:13)
Block(1,8,0,17:13)
Block(1,8,1,17:13)
Block(1,9,-1,17:13)
Block(1,9,0,17:13)
Block(1,10,-1,17:13)
Block(1,10,0,17:13)
Block(1,11,-1,17:13)
Block(1,11,0,17:13)
Block(1,13,10,159:1)
Block(1,13,11,179:2)
Block(1,14,8,179:2)
Block(1,14,12,159:1)
Block(1,15,9,179:2)
Block(1,15,10,179:2)
Block(1,15,11,159:1)
Block(1,15,12,159:1)
Block(1,16,7,159:1)
Block(1,16,10,17:13)
Block(1,16,11,17:13)
Block(1,16,12,179:2)
Block(1,16,13,159:1)
Block(1,17,8,179:2)
Block(1,17,9,179:2)
Block(1,18,-13,179:2)
Block(1,18,-12,179:2)
Block(1,18,-11,159:1)
Block(1,18,0,126:4)
Block(1,18,1,179:2)
Block(1,18,5,179:2)
Block(1,18,6,159:1)
Block(1,18,8,179:2)
Block(1,19,-13,179:2)
Block(1,19,-8,159:1)
Block(1,19,-5,17:13)
Block(1,19,-4,17:13)
Block(1,19,-2,182)
Block(1,19,1,179:2)
Block(1,19,6,179:2)
Block(1,19,7,159:1)
Block(1,20,-13,182)
Block(1,20,-7,159:1)
Block(1,20,-6,159:1)
Block(1,20,-3,182)
Block(1,20,1,179:2)
Block(1,21,-13,182)
Block(1,21,-8,159:1)
Block(1,21,-7,182)
Block(1,21,-6,159:1)
Block(1,21,-4,179:2)
Block(1,21,-2,17:13)
Block(1,21,-1,17:13)
Block(1,21,0,159:1)
Block(1,22,-7,179:2)
Block(1,22,-6,159:1)
Block(1,22,-5,159:1)
Block(1,22,-3,126:4)
Block(1,22,-2,179:2)
Block(1,22,-1,17:13)
Block(1,22,3,159:1)
Block(1,23,-9,179:2)
Block(1,23,-3,159:1)
Block(1,23,1,159:1)
Block(1,23,2,126:4)
Block(1,23,3,126:4)
Block(1,24,-4,179:2)
Block(1,24,-3,126:4)
Block(1,24,-2,179:2)
Block(1,24,0,179:2)
Block(1,25,-6,179:2)
Block(2,1,-4,17:13)
Block(2,2,-4,17:13)
Block(2,2,-3,17:13)
Block(2,9,0,17:13)
Block(2,10,-1,17:13)
Block(2,10,0,17:13)
Block(2,11,-1,17:13)
Block(2,12,-2,17:13)
Block(2,12,-1,17:13)
Block(2,13,-1,17:13)
Block(2,13,9,179:2)
Block(2,13,10,179:2)
Block(2,15,8,179:2)
Block(2,15,10,179:2)
Block(2,15,11,179:2)
Block(2,16,-9,179:2)
Block(2,16,8,159:1)
Block(2,16,10,17:13)
Block(2,16,12,179:2)
Block(2,17,-14,159:1)
Block(2,17,-10,17:13)
Block(2,17,-9,17:13)
Block(2,17,-8,17:13)
Block(2,17,-6,159:1)
Block(2,17,9,17:13)
Block(2,17,10,17:13)
Block(2,18,-11,159:1)
Block(2,18,-10,17:13)
Block(2,18,-6,17:13)
Block(2,18,-5,17:13)
Block(2,19,-14,126:4)
Block(2,19,-9,179:2)
Block(2,19,-5,17:13)
Block(2,19,-4,17:13)
Block(2,19,10,159:1)
Block(2,20,-13,179:2)
Block(2,20,-12,159:1)
Block(2,20,-11,159:1)
Block(2,20,-8,179:2)
Block(2,20,-6,179:2)
Block(2,20,-5,159:1)
Block(2,20,0,179:2)
Block(2,20,2,159:1)
Block(2,21,-13,182)
Block(2,21,-4,159:1)
Block(2,21,0,179:2)
Block(2,21,1,159:1)
Block(2,22,-7,179:2)
Block(2,22,-5,159:1)
Block(2,22,-1,17:13)
Block(2,22,0,17:13)
Block(2,22,1,179:2)
Block(2,22,2,179:2)
Block(2,22,3,159:1)
Block(2,23,-5,179:2)
Block(2,23,-1,179:2)
Block(2,23,0,17:13)
Block(2,24,-7,179:2)
Block(2,25,0,159:1)
Block(3,0,-5,17:13)
Block(3,0,-4,188)
Block(3,1,-5,17:13)
Block(3,1,-4,17:13)
Block(3,2,-4,17:13)
Block(3,2,-3,17:13)
Block(3,11,-1,17:13)
Block(3,12,-3,17:13)
Block(3,12,-2,17:13)
Block(3,12,-1,17:13)
Block(3,13,-4,17:13)
Block(3,13,-3,17:13)
Block(3,13,-2,17:13)
Block(3,13,-1,17:13)
Block(3,13,0,17:13)
Block(3,14,0,17:13)
Block(3,15,9,126:4)
Block(3,15,10,179:2)
Block(3,16,-10,179:2)
Block(3,16,4,159:1)
Block(3,16,7,126:4)
Block(3,16,8,159:1)
Block(3,16,10,182)
Block(3,17,-9,17:13)
Block(3,17,-8,17:13)
Block(3,17,-7,17:13)
Block(3,17,6,179:2)
Block(3,17,7,17:13)
Block(3,17,8,17:13)
Block(3,17,9,17:13)
Block(3,17,12,179:2)
Block(3,18,-11,17:13)
Block(3,18,-10,17:13)
Block(3,18,-8,179:2)
Block(3,18,-7,17:13)
Block(3,18,-6,17:13)
Block(3,18,6,179:2)
Block(3,18,7,126:4)
Block(3,18,11,159:1)
Block(3,19,-9,159:1)
Block(3,19,-8,159:1)
Block(3,19,-5,159:1)
Block(3,20,-11,159:1)
Block(3,20,-9,179:2)
Block(3,20,-7,159:1)
Block(3,20,-6,159:1)
Block(3,21,-11,159:1)
Block(3,21,-9,179:2)
Block(3,21,-7,179:2)
Block(3,21,-6,159:1)
Block(3,21,-5,159:1)
Block(3,21,0,179:2)
Block(3,21,1,179:2)
Block(3,22,-6,179:2)
Block(3,22,-5,179:2)
Block(3,22,-3,159:1)
Block(3,22,0,179:2)
Block(3,22,1,159:1)
Block(3,22,2,159:1)
Block(3,23,-5,179:2)
Block(3,23,-4,179:2)
Block(3,23,-3,179:2)
Block(3,23,3,179:2)
Block(3,24,-5,159:1)
Block(3,24,-2,179:2)
Block(3,25,1,179:2)
Block(4,0,-6,17:13)
Block(4,0,-5,17:13)
Block(4,1,-5,188)
Block(4,9,6,182)
Block(4,9,7,126:4)
Block(4,10,5,182)
Block(4,11,5,159:1)
Block(4,12,-4,17:13)
Block(4,12,-3,17:13)
Block(4,12,-2,182)
Block(4,12,-1,17:13)
Block(4,13,-5,17:13)
Block(4,13,-4,17:13)
Block(4,13,-1,17:13)
Block(4,13,0,17:13)
Block(4,13,3,159:1)
Block(4,14,-5,17:13)
Block(4,14,-4,17:13)
Block(4,14,0,17:13)
Block(4,14,3,159:1)
Block(4,14,6,126:4)
Block(4,14,9,182)
Block(4,15,-11,159:1)
Block(4,15,6,159:1)
Block(4,15,7,159:1)
Block(4,15,8,179:2)
Block(4,15,10,179:2)
Block(4,16,-7,17:13)
Block(4,16,-6,17:13)
Block(4,16,4,17:13)
Block(4,16,5,17:13)
Block(4,16,6,17:13)
Block(4,16,7,179:2)
Block(4,16,8,182)
Block(4,16,9,159:1)
Block(4,16,10,179:2)
Block(4,17,-13,159:1)
Block(4,17,-10,179:2)
Block(4,17,-7,17:13)
Block(4,17,5,182)
Block(4,17,6,17:13)
Block(4,17,7,17:13)
Block(4,17,8,179:2)
Block(4,17,9,182)
Block(4,18,-12,159:1)
Block(4,18,-11,17:13)
Block(4,18,-8,159:1)
Block(4,18,-6,179:2)
Block(4,19,-9,159:1)
Block(4,19,-7,179:2)
Block(4,20,-12,159:1)
Block(4,20,-11,179:2)
Block(4,20,-9,182)
Block(4,20,-7,159:1)
Block(4,20,-1,159:1)
Block(4,20,0,159:1)
Block(4,21,-11,179:2)
Block(4,21,-8,159:1)
Block(4,21,-3,179:2)
Block(4,21,-1,179:2)
Block(4,22,-6,179:2)
Block(4,22,-5,179:2)
Block(4,22,-3,159:1)
Block(4,22,0,159:1)
Block(4,23,-5,159:1)
Block(4,24,-5,126:4)
Block(4,24,-2,159:1)
Block(4,24,0,179:2)
Block(4,24,2,159:1)
Block(5,0,-6,17:13)
Block(5,0,-5,17:13)
Block(5,6,6,17:13)
Block(5,7,6,17:13)
Block(5,8,5,182)
Block(5,8,6,17:13)
Block(5,9,5,17:13)
Block(5,9,6,17:13)
Block(5,10,4,182)
Block(5,10,5,17:13)
Block(5,10,6,179:2)
Block(5,12,-4,17:13)
Block(5,13,-5,17:13)
Block(5,13,-4,17:13)
Block(5,13,-1,17:13)
Block(5,13,0,182)
Block(5,13,2,159:1)
Block(5,13,3,126:4)
Block(5,14,-5,17:13)
Block(5,14,-1,182)
Block(5,14,0,17:13)
Block(5,14,1,17:13)
Block(5,14,2,182)
Block(5,14,3,17:13)
Block(5,14,4,182)
Block(5,14,5,179:2)
Block(5,14,6,159:1)
Block(5,15,-6,17:13)
Block(5,15,-5,17:13)
Block(5,15,0,17:13)
Block(5,15,1,17:13)
Block(5,15,3,17:13)
Block(5,15,4,17:13)
Block(5,15,5,159:1)
Block(5,15,6,159:1)
Block(5,16,-9,179:2)
Block(5,16,-7,17:13)
Block(5,16,-6,17:13)
Block(5,16,3,126:4)
Block(5,16,4,17:13)
Block(5,16,6,182)
Block(5,17,-11,159:1)
Block(5,17,-7,179:2)
Block(5,17,5,179:2)
Block(5,18,-10,182)
Block(5,18,-9,182)
Block(5,18,-7,179:2)
Block(5,18,-6,159:1)
Block(5,19,-11,159:1)
Block(5,19,-10,159:1)
Block(5,19,-9,159:1)
Block(5,19,-8,159:1)
Block(5,19,-5,179:2)
Block(5,20,-11,179:2)
Block(5,20,-10,179:2)
Block(5,20,-6,179:2)
Block(5,21,-9,159:1)
Block(5,21,-8,159:1)
Block(5,21,-7,159:1)
Block(5,21,-3,179:2)
Block(5,21,0,159:1)
Block(5,22,-10,179:2)
Block(5,22,-9,159:1)
Block(5,22,-6,159:1)
Block(5,22,-4,159:1)
Block(5,22,0,159:1)
Block(5,23,-9,159:1)
Block(5,23,-8,179:2)
Block(5,23,-6,179:2)
Block(5,24,-8,159:1)
Block(5,24,-7,159:1)
Block(5,24,-6,179:2)
Block(6,9,5,182)
Block(6,9,6,126:4)
Block(6,10,4,17:13)
Block(6,10,5,17:13)
Block(6,11,4,17:13)
Block(6,11,5,159:1)
Block(6,12,4,17:13)
Block(6,13,2,17:13)
Block(6,13,3,17:13)
Block(6,13,4,179:2)
Block(6,14,-6,17:13)
Block(6,14,-5,17:13)
Block(6,14,1,17:13)
Block(6,14,2,17:13)
Block(6,14,3,17:13)
Block(6,15,-6,17:13)
Block(6,15,-5,17:13)
Block(6,15,3,182)
Block(6,15,5,179:2)
Block(6,15,7,179:2)
Block(6,16,6,179:2)
Block(6,17,-10,159:1)
Block(6,18,-11,159:1)
Block(6,18,-6,159:1)
Block(6,19,-12,179:2)
Block(6,19,-10,159:1)
Block(6,19,-9,159:1)
Block(6,19,-4,179:2)
Block(6,19,-2,17:13)
Block(6,19,-1,17:13)
Block(6,20,-5,159:1)
Block(6,20,-1,17:13)
Block(6,20,0,17:13)
Block(6,20,3,159:1)
Block(6,21,-8,179:2)
Block(6,21,-3,179:2)
Block(6,21,0,17:13)
Block(6,21,1,17:13)
Block(6,22,-9,159:1)
Block(6,22,-7,179:2)
Block(6,22,-6,159:1)
Block(6,22,-4,179:2)
Block(6,22,-1,179:2)
Block(6,22,0,179:2)
Block(6,22,5,179:2)
Block(6,23,-9,179:2)
Block(6,23,0,179:2)
Block(6,23,1,179:2)
Block(6,24,-6,159:1)
Block(6,24,-2,159:1)
Block(7,11,4,179:2)
Block(7,12,4,17:13)
Block(7,13,3,17:13)
Block(7,13,4,17:13)
Block(7,14,3,17:13)
Block(7,15,-5,17:13)
Block(7,15,4,182)
Block(7,16,-6,179:2)
Block(7,16,-5,17:13)
Block(7,16,-4,17:13)
Block(7,17,-11,179:2)
Block(7,17,-8,179:2)
Block(7,17,-7,159:1)
Block(7,17,-4,17:13)
Block(7,17,-3,17:13)
Block(7,18,-3,17:13)
Block(7,18,-2,17:13)
Block(7,19,-10,159:1)
Block(7,19,-8,179:2)
Block(7,19,-2,17:13)
Block(7,19,0,179:2)
Block(7,19,2,159:1)
Block(7,20,-5,179:2)
Block(7,20,-3,159:1)
Block(7,20,0,159:1)
Block(7,20,1,179:2)
Block(7,20,2,179:2)
Block(7,21,-7,179:2)
Block(7,21,-5,179:2)
Block(7,21,-4,179:2)
Block(7,21,-3,159:1)
Block(7,21,-1,159:1)
Block(7,21,0,159:1)
Block(7,21,1,17:13)
Block(7,21,2,17:13)
Block(7,22,-5,159:1)
Block(7,22,-4,179:2)
Block(7,22,-2,159:1)
Block(7,22,-1,159:1)
Block(7,22,0,179:2)
Block(7,22,2,17:13)
Block(7,22,5,159:1)
Block(7,23,-7,179:2)
Block(7,23,-4,159:1)
Block(7,23,-2,159:1)
Block(7,23,-1,159:1)
Block(7,23,0,159:1)
Block(7,23,5,159:1)
Block(7,24,-5,126:4)
Block(7,24,2,159:1)
Block(7,25,-4,159:1)
Block(7,25,-3,159:1)
Block(7,25,2,179:2)
Block(7,25,3,179:2)
Block(8,10,5,17:13)
Block(8,11,4,159:1)
Block(8,11,5,17:13)
Block(8,12,3,182)
Block(8,12,4,17:13)
Block(8,12,5,17:13)
Block(8,12,6,126:4)
Block(8,13,4,17:13)
Block(8,15,-5,17:13)
Block(8,15,-4,17:13)
Block(8,17,-4,182)
Block(8,18,-5,179:2)
Block(8,18,-3,159:1)
Block(8,18,0,159:1)
Block(8,19,-9,159:1)
Block(8,19,-2,179:2)
Block(8,19,1,159:1)
Block(8,20,-7,179:2)
Block(8,20,-1,179:2)
Block(8,20,0,159:1)
Block(8,20,2,159:1)
Block(8,20,4,179:2)
Block(8,21,-7,159:1)
Block(8,21,-5,179:2)
Block(8,21,-3,159:1)
Block(8,21,-1,159:1)
Block(8,21,0,159:1)
Block(8,21,1,159:1)
Block(8,21,2,159:1)
Block(8,22,-2,179:2)
Block(8,22,5,159:1)
Block(8,23,-1,159:1)
Block(8,23,2,159:1)
Block(8,23,5,179:2)
Block(8,24,-4,159:1)
Block(8,24,2,159:1)
Block(9,10,4,182)
Block(9,10,5,17:13)
Block(9,10,6,17:13)
Block(9,11,5,182)
Block(9,15,-5,17:13)
Block(9,15,-4,17:13)
Block(9,17,-2,179:2)
Block(9,18,-5,182)
Block(9,18,-4,159:1)
Block(9,18,0,179:2)
Block(9,18,1,159:1)
Block(9,19,-6,159:1)
Block(9,19,-2,159:1)
Block(9,19,-1,179:2)
Block(9,19,0,159:1)
Block(9,19,1,179:2)
Block(9,20,-8,179:2)
Block(9,20,-4,179:2)
Block(9,20,-3,179:2)
Block(9,20,-2,159:1)
Block(9,20,0,179:2)
Block(9,21,-6,159:1)
Block(9,21,-1,159:1)
Block(9,21,0,159:1)
Block(9,22,-2,179:2)
Block(9,22,0,159:1)
Block(9,22,2,159:1)
Block(9,23,-2,179:2)
Block(9,23,-1,179:2)
Block(9,23,0,179:2)
Block(9,23,2,179:2)
Block(9,23,4,126:4)
Block(9,24,-1,159:1)
Block(9,24,2,179:2)
Block(9,24,5,182)
Block(10,8,6,17:13)
Block(10,9,6,17:13)
Block(10,10,6,17:13)
Block(10,11,7,179:2)
Block(10,15,-4,17:13)
Block(10,15,-3,17:13)
Block(10,16,-7,179:2)
Block(10,16,-4,17:13)
Block(10,16,-2,159:1)
Block(10,17,-4,179:2)
Block(10,18,-7,159:1)
Block(10,18,-5,179:2)
Block(10,18,-4,159:1)
Block(10,19,-1,159:1)
Block(10,21,-4,159:1)
Block(10,21,-1,179:2)
Block(10,22,-4,126:4)
Block(10,22,-3,159:1)
Block(10,22,-2,179:2)
Block(10,23,-2,182)
Block(10,23,3,179:2)
Block(11,7,6,17:13)
Block(11,8,6,17:13)
Block(11,10,6,126:4)
Block(11,14,-5,179:2)
Block(11,15,-7,179:2)
Block(11,15,-6,179:2)
Block(11,15,-4,17:13)
Block(11,16,-5,17:13)
Block(11,16,-4,17:13)
Block(11,17,-6,159:1)
Block(11,17,-5,159:1)
Block(11,17,-3,159:1)
Block(11,17,-2,179:2)
Block(11,18,-8,159:1)
Block(11,18,-7,159:1)
Block(11,18,-6,159:1)
Block(11,18,-5,159:1)
Block(11,18,-2,179:2)
Block(11,18,-1,179:2)
Block(11,19,-7,179:2)
Block(11,19,-6,159:1)
Block(11,19,-5,159:1)
Block(11,19,-3,159:1)
Block(11,19,-2,179:2)
Block(11,20,-4,159:1)
Block(11,20,-3,179:2)
Block(11,20,-2,179:2)
Block(11,21,-5,179:2)
Block(11,21,0,159:1)
Block(11,22,-1,159:1)
Block(11,22,0,159:1)
Block(11,22,2,159:1)
Block(11,23,1,159:1)
Block(12,14,-3,159:1)
Block(12,15,-6,159:1)
Block(12,15,-5,179:2)
Block(12,15,-4,179:2)
Block(12,15,-3,159:1)
Block(12,16,-6,17:13)
Block(12,16,-5,17:13)
Block(12,16,-2,159:1)
Block(12,16,-1,159:1)
Block(12,16,0,159:1)
Block(12,16,1,159:1)
Block(12,17,-9,159:1)
Block(12,17,-5,17:13)
Block(12,17,-2,159:1)
Block(12,17,0,179:2)
Block(12,18,-6,159:1)
Block(12,18,-4,159:1)
Block(12,18,-3,179:2)
Block(12,18,-2,179:2)
Block(12,19,-6,159:1)
Block(12,20,-7,179:2)
Block(12,20,-6,179:2)
Block(12,20,-2,179:2)
Block(12,20,-1,159:1)
Block(12,21,-1,179:2)
Block(13,14,-2,159:1)
Block(13,15,-6,159:1)
Block(13,16,-6,179:2)
Block(13,16,-4,179:2)
Block(13,17,-4,159:1)
Block(13,17,1,179:2)
Block(13,18,-6,179:2)
Block(13,18,-5,159:1)
Block(13,18,-4,179:2)
Block(13,18,-2,179:2)
Block(13,19,-5,179:2)
Block(13,19,-1,179:2)
Block(13,20,-8,159:1)
Block(13,20,-4,159:1)
Block(14,15,-2,179:2)
Block(14,15,-1,179:2)
Block(14,17,-7,179:2)
Block(14,17,-2,159:1)
Block(14,18,-2,179:2)


#######################################################################
# +-----------------------------------------------------------------+ #
# |                             Entities                            | #
# +-----------------------------------------------------------------+ #
#######################################################################

# Entity() spawns an entity instead of a block. The entity is spawned only once when the BO3 is spawned.
# Entities are persistent by default so they don't de-spawn when no player is near, they are only unloaded.
# Usage: Entity(x,y,z,mobName,groupSize,NameTagOrNBTFileName) or Entity(x,y,z,mobName,groupSize)
# Use /tc entities or /otg entities to get a list of entities that can be used as mobName, this includes entities added by other mods.
# NameTagOrNBTFileName can be either a nametag for the mob or an nbt file (such as mymobinfo.nbt or mymobinfo.txt).
# When using a text file you can use the same mob spawning parameters used with the /summon command to equip the
# entity and give it custom attributes etc. You can copy the DATA part of a summon command including surrounding
# curly braces to a .txt file, for instance for: "/summon Skeleton x y z {DATA}"

#######################################################################
# +-----------------------------------------------------------------+ #
# |                            BO3 checks                           | #
# +-----------------------------------------------------------------+ #
#######################################################################

# Require a condition at a certain location in order for the BO3 to be spawned.
# BlockCheck(x,y,z,BlockName[,BlockName[,...]]) - one of the blocks must be at the location
# BlockCheckNot(x,y,z,BlockName[,BlockName[,...]]) - all the blocks must not be at the location
# LightCheck(x,y,z,minLightLevel,maxLightLevel) - light must be between min and max (inclusive)

# You can use "Solid" as a BlockName for matching all solid blocks or "All" to match all blocks that aren't air.

# Examples:
#   BlockCheck(0,-1,0,GRASS,DIRT)  Require grass or dirt just below the object
#   BlockCheck(0,-1,0,Solid)       Require any solid block just below the object
#   BlockCheck(0,-1,0,WOOL)        Require any type of wool just below the object
#   BlockCheck(0,-1,0,WOOL:0)      Require white wool just below the object
#   BlockCheckNot(0,-1,0,WOOL:0)   Require that there is no white wool below the object
#   LightCheck(0,0,0,0,1)          Require almost complete darkness just below the object
BlockCheck(0,-1,0,GRASS,DIRT)
